Workbook

Sheet Miodrag MILIC
B2: LIVRE DE PAIE | D2: 2024 | F2: SALAIRES PLUS AVANCES MALADIE | L2: MATRICULE N° 1989 11 24 004 47
A4: Groupe Advensys Luxembourg SA
A5: Duarrefstrooss 49 | E5: Ancienneté | G5: 42832 | J5: D588378 | L5: Miodrag MILIC | P5: N° 1
A6: L-9964 HULDANGE | E6: Entrée | G6: 42832 | L6: 52, Grand-Rue
A7: 2015 22 06 748 | E7: Sortie | L7: L-9711 CLERVAUX
A9: Jours | B9: Jours impos. | C9: Stat. | D9: Classe - % | E9: Rémun. Base | F9: Brut Mensuel | G9: Cotisable | H9: Maladie | I9: Pension | J9: CI-CO2 | K9: Déductions | L9: Imposable | M9: Impots | N9: CIS | O9: CISSM | P9: Salaire Net
A10: J 1-31 | B10: 25 | C10: Empl. | D10: 15% - 2 | E10: 2570.935 | F10: 2570.935 | G10: =F10 -> 2570.935 | H10: =71.99+6.43 -> 78.42 | I10: 205.67 | J10: 14 | K10: =33+460 -> 493 | L10: 1793.84 | M10: 269.08 | N10: 50 | O10: 70 | P10: 2659
A11: F 1-29 | B11: 25 | C11: Empl. | D11: 15% - 2 | E11: 2570.935 | F11: 2570.935 | G11: =F11 -> 2570.935 | H11: =71.99+6.43 -> 78.42 | I11: 205.67 | J11: 14 | K11: =33+460 -> 493 | L11: 1793.84 | M11: 268.5 | N11: 50 | O11: 70 | P11: 2425.11
A12: M 1-31 | B12: 25 | C12: Empl. | D12: 15% - 2 | E12: 2570.935 | F12: 2570.935 | G12: =F12 -> 2570.935 | H12: =71.99+6.43 -> 78.42 | I12: 205.67 | J12: 14 | K12: =33+460 -> 493 | L12: 1793.84 | M12: 268.5 | N12: 50 | O12: 70 | P12: 2369.34
A13: A 1-30 | B13: 25 | C13: Empl. | D13: 15% - 2 | E13: 2570.935 | F13: 2570.935 | G13: =F13 -> 2570.935 | H13: =71.99+6.43 -> 78.42 | I13: 205.67 | J13: 14 | K13: =33+460 -> 493 | L13: 1793.84 | M13: 268.5 | N13: 50 | O13: 70 | P13: 2209.34
A14: M 1-31 | B14: 25 | C14: Empl. | D14: 15% - 2 | E14: 2570.935 | F14: 2570.935 | G14: =F14 -> 2570.935 | H14: =71.99+6.43 -> 78.42 | I14: 205.67 | J14: 14 | K14: =33+460 -> 493 | L14: 1793.84 | M14: 268.5 | N14: 50 | O14: 70 | P14: 3004.34
A15: J 1-30 | B15: 25 | C15: Empl. | D15: 15% - 2 | E15: 2570.935 | F15: 2570.935 | G15: =F15 -> 2570.935 | H15: =71.99+6.43 -> 78.42 | I15: 205.67 | J15: 14 | K15: =33+460 -> 493 | L15: 1793.84 | M15: 268.5 | N15: 50 | O15: 70 | P15: 2509.34
A16: J 1-31 | B16: 25 | C16: Empl. | D16: 15% - 2 | E16: 2570.935 | F16: 2570.935 | G16: =F16 -> 2570.935 | H16: =71.99+6.43 -> 78.42 | I16: 205.67 | J16: 14 | K16: =33+460 -> 493 | L16: 1793.84 | M16: 268.5 | N16: 50 | O16: 70 | P16: 2880.34
A17: A 1-31 | B17: 25 | C17: Empl. | D17: 15% - 2 | E17: 2570.935 | F17: 2570.935 | G17: =F17 -> 2570.935 | H17: =71.99+6.43 -> 78.42 | I17: 205.67 | J17: 14 | K17: =33+460 -> 493 | L17: 1793.84 | M17: 268.5 | N17: 50 | O17: 70 | P17: 2569.34
A18: S 1-30 | B18: 25 | C18: Empl. | D18: 15% - 2 | E18: 2570.94 | F18: 2570.94 | G18: =F18 -> 2570.94 | H18: =71.99+6.43 -> 78.42 | I18: 205.67 | J18: 14 | K18: =33+460 -> 493 | L18: 1793.84 | M18: 268.5 | N18: 50 | O18: 70 | P18: 2669.34
A19: O 1-31 | B19: 25 | C19: Empl. | D19: 15% - 2 | E19: 2570.93 | F19: 2570.93 | G19: =F19 -> 2570.93 | H19: =71.99+6.43 -> 78.42 | I19: 205.67 | J19: 14 | K19: =33+460 -> 493 | L19: 1793.84 | M19: 268.5 | N19: 50 | O19: 70 | P19: 2529.34
A20: N 1-30 | B20: 25 | C20: Empl. | D20: 2 | E20: 2570.93 | F20: 2570.93 | G20: =F20 -> 2570.93 | H20: =71.99+6.43 -> 78.42 | I20: 205.67 | J20: 14 | K20: 33 | L20: 2253.84 | M20: 7.8 | N20: 50 | O20: 70 | P20: 2675.04
A21: D 1-31 | B21: 25 | C21: Empl. | D21: 2 | E21: 2570.94 | F21: 2570.94 | G21: =F21 -> 2570.94 | H21: =71.99+6.43 -> 78.42 | I21: 205.67 | J21: 14 | K21: 33 | L21: 2253.84 | M21: 7.8 | N21: 50 | O21: 70 | P21: 3055.54
E22: =SUM(E10:E21) -> 30851.22 | F22: =SUM(F10:F21) -> 30851.22 | G22: =SUM(G10:G21) -> 30851.22 | H22: =SUM(H10:H21) -> 941.04 | I22: =SUM(I10:I21) -> 2468.04 | J22: =SUM(J10:J21) -> 168 | K22: =SUM(K10:K21) -> 4996 | L22: =SUM(L10:L21) -> 22446.08 | ... P22: =SUM(P10:P21) -> 31555.41
A25: Heures | B25: Normal | C25: Suppl. | D25: Congés | E25: Férié extra | F25: Congés familliale (COVID-19) | G25: Maladie | H25: RECAPITULATION ANNEE
H26: Imposable | J26: Impot | K26: NET
A27: J | B27: 173 | D27: 16 | E27: 8 | H27: =L10 -> 1793.84 | J27: =M10 -> 269.08 | K27: =P10 -> 2659
A28: F | B28: 173 | D28: 24 | G28: 16 | H28: =L11 -> 1793.84 | J28: =M11 -> 268.5 | K28: =P11 -> 2425.11
A29: M | B29: 173 | H29: =L12 -> 1793.84 | J29: =M12 -> 268.5 | K29: =P12 -> 2369.34
A30: A | B30: 173 | D30: 40 | E30: 8 | H30: =L13 -> 1793.84 | J30: =M13 -> 268.5 | K30: =P13 -> 2209.34
A31: M | B31: 173 | D31: 12 | E31: 24 | H31: =L14 -> 1793.84 | J31: =M14 -> 268.5 | K31: =P14 -> 3004.34
A32: J | B32: 173 | D32: 16 | E32: 16 | G32: 8 | H32: =L15 -> 1793.84 | J32: =M15 -> 268.5 | K32: =P15 -> 2509.34
A33: J | B33: 173 | H33: =L16 -> 1793.84 | J33: =M16 -> 268.5 | K33: =P16 -> 2880.34
A34: A | B34: 173 | D34: 80 | E34: 8 | H34: =L17 -> 1793.84 | J34: =M17 -> 268.5 | K34: =P17 -> 2569.34
A35: S | B35: 173 | D35: 8 | H35: =L18 -> 1793.84 | J35: =M18 -> 268.5 | K35: =P18 -> 2669.34
A36: O | B36: 173 | D36: 36 | H36: =L19 -> 1793.84 | J36: =M19 -> 268.5 | K36: =P19 -> 2529.34
A37: N | B37: 173 | E37: 8 | H37: =L20 -> 2253.84 | J37: =M20 -> 7.8 | K37: =P20 -> 2675.04
A38: D | B38: 173 | D38: 44 | E38: 16 | H38: =L21 -> 2253.84 | J38: =M21 -> 7.8 | K38: =P21 -> 3055.54
B39: =SUM(B27:B38) -> 2076 | C39: =SUM(C27:C38) -> 0 | D39: =SUM(D27:D38) -> 276 | E39: =SUM(E27:E38) -> 88 | F39: =SUM(F27:F38) -> 0 | G39: =SUM(G27:G38) -> 24 | H39: =SUM(H27:H38) -> 22446.08 | J39: =SUM(J27:J38) -> 2701.18 | K39: =SUM(K27:K38) -> 31555.41

Sheet BERTHE Alexandra
B2: LIVRE DE PAIE | D2: 2024 | F2: SALAIRES PLUS AVANCES MALADIE | L2: MATRICULE N° 1996 09 05 124 86
A4: Groupe Advensys Luxembourg SA
A5: Duarrefstrooss 49 | E5: Ancienneté | G5: =G6 -> 44455 | J5: D608388-2022 | L5: BERTHE Alexandra | P5: N° 2
A6: L-9964 HULDANGE | E6: Entrée | G6: 44455 | L6: 93, Duarrefstrooss
A7: 2015 22 06 748 | E7: Sortie | L7: L-9964 Huldange
A9: Jours | B9: Jours impos. | C9: Stat. | D9: Classe - % | E9: Rémun. Base | F9: Brut Mensuel | G9: Cotisable | H9: Maladie | I9: Pension | J9: CI-CO2 | K9: Déductions | L9: Imposable | M9: Impots | N9: CIS | O9: CISSM | P9: Salaire Net
A10: J 1-31 | B10: 25 | C10: Empl. | D10: 1 | E10: 2570.93 | F10: 2570.93 | G10: =F10 -> 2570.93 | H10: =71.99+6.43 -> 78.42 | I10: 205.67 | J10: 14 | K10: 0 | L10: 2286.84 | M10: 149.3 | N10: 50 | O10: 70 | P10: 1244.54
A11: F 1-29 | B11: 25 | C11: Empl. | D11: 1 | E11: 2570.93 | F11: 2570.93 | G11: =F11 -> 2570.93 | H11: =71.99+6.43 -> 78.42 | I11: 205.67 | J11: 14 | K11: 0 | L11: 2286.84 | M11: 139.9 | N11: 50 | O11: 70 | P11: 1259.94
A12: M 1-31 | B12: 25 | C12: Empl. | D12: 1 | E12: 2570.93 | F12: 2570.93 | G12: =F12 -> 2570.93 | H12: =71.99+6.43 -> 78.42 | I12: 205.67 | J12: 14 | K12: 0 | L12: 2286.84 | M12: 139.9 | N12: 50 | O12: 70 | P12: 1253.94
A13: A 1-30 | B13: 25 | C13: Empl. | D13: 1 | E13: 2570.93 | F13: 2570.93 | G13: =F13 -> 2570.93 | H13: =71.99+6.43 -> 78.42 | I13: 205.67 | J13: 14 | K13: 0 | L13: 2286.84 | M13: 139.9 | N13: 50 | O13: 70 | P13: 1218.94
A14: M 1-31 | B14: 25 | C14: Empl. | D14: 1 | E14: 2570.93 | F14: 2570.93 | G14: =F14 -> 2570.93 | H14: =71.99+6.43 -> 78.42 | I14: 205.67 | J14: 14 | K14: 0 | L14: 2286.84 | M14: 139.9 | N14: 50 | O14: 70 | P14: 1474.94
A15: J 1-30 | B15: 25 | C15: Empl. | D15: 1 | E15: 2570.93 | F15: 2570.93 | G15: =F15 -> 2570.93 | H15: =71.99+6.43 -> 78.42 | I15: 205.67 | J15: 14 | K15: 0 | L15: 2286.84 | M15: 139.9 | N15: 50 | O15: 70 | P15: 1197.94
A16: J 1-31 | B16: 25 | C16: Empl. | D16: 1 | E16: 2570.93 | F16: 2570.93 | G16: =F16 -> 2570.93 | H16: =71.99+6.43 -> 78.42 | I16: 205.67 | J16: 14 | K16: 0 | L16: 2286.84 | M16: 139.9 | N16: 50 | O16: 70 | P16: 1197.94
A17: A 1-31 | B17: 25 | C17: Empl. | D17: 1 | E17: 2570.93 | F17: 2570.93 | G17: =F17 -> 2570.93 | H17: =71.99+6.43 -> 78.42 | I17: 205.67 | J17: 14 | K17: 0 | L17: 2286.84 | M17: 139.9 | N17: 50 | O17: 70 | P17: 1197.94
A18: S 1-30 | B18: 25 | C18: Empl. | D18: 1 | E18: 2758.17 | F18: 2758.17 | G18: =F18 -> 2758.17 | H18: =77.23+6.9 -> 84.13 | I18: 220.65 | J18: 14 | K18: 0 | L18: 2453.39 | M18: 170.4 | N18: 50 | O18: 70 | P18: 1331.38
A19: O 1-31 | B19: 25 | C19: Empl. | D19: 1 | E19: 3085.11 | F19: 3085.11 | G19: =F19 -> 3085.11 | H19: =86.38+7.71 -> 94.09 | I19: 246.81 | J19: 14 | K19: 0 | L19: 2744.2 | M19: 231.8 | N19: 50 | O19: 60.07 | P19: 1546.28
A20: N 1-30 | B20: 25 | C20: Empl. | D20: 1 | E20: 3085.11 | F20: 3085.11 | G20: =F20 -> 3085.11 | H20: =86.38+7.71 -> 94.09 | I20: 246.81 | J20: 14 | K20: 0 | L20: 2744.2 | M20: 231.8 | N20: 50 | O20: 60.07 | P20: 1546.28
A21: D 1-31 | B21: 25 | C21: Empl. | D21: 1 | E21: 3085.11 | F21: 3085.11 | G21: =F21 -> 3085.11 | H21: =86.38+7.71 -> 94.09 | I21: 246.81 | J21: 14 | K21: 0 | L21: 2744.2 | M21: 231.8 | N21: 50 | O21: 60.07 | P21: 1896.28
E22: =SUM(E10:E21) -> 32580.94 | F22: =SUM(F10:F21) -> 32580.94 | G22: =SUM(G10:G21) -> 32580.94 | H22: =SUM(H10:H21) -> 993.76 | I22: =SUM(I10:I21) -> 2606.44 | J22: =SUM(J10:J21) -> 168 | K22: =SUM(K10:K21) -> 0 | L22: =SUM(L10:L21) -> 28980.71 | ... P22: =SUM(P10:P21) -> 16366.34
A25: Heures | B25: Normal | C25: Suppl. | D25: Congés | E25: Férié extra | F25: Chômage | G25: Maladie | H25: RECAPITULATION ANNEE
H26: Imposable | J26: Impot | K26: NET
A27: J | B27: 173 | D27: 8 | E27: 8 | G27: 16 | H27: =M10 -> 149.3 | J27: =N10 -> 50 | K27: =P10 -> 1244.54
A28: F | B28: 173 | D28: 16 | H28: =M11 -> 139.9 | J28: =N11 -> 50 | K28: =P11 -> 1259.94
A29: M | B29: 173 | H29: =M12 -> 139.9 | J29: =N12 -> 50 | K29: =P12 -> 1253.94
A30: A | B30: 173 | D30: 24 | E30: 8 | G30: 24 | H30: =M13 -> 139.9 | J30: =N13 -> 50 | K30: =P13 -> 1218.94
A31: M | B31: 173 | D31: 8 | E31: 32 | H31: =M14 -> 139.9 | J31: =N14 -> 50 | K31: =P14 -> 1474.94
A32: J | B32: 173 | D32: 40 | E32: 16 | H32: =M15 -> 139.9 | J32: =N15 -> 50 | K32: =P15 -> 1197.94
A33: J | B33: 173 | H33: =M16 -> 139.9 | J33: =N16 -> 50 | K33: =P16 -> 1197.94
A34: A | B34: 173 | D34: 80 | E34: 8 | H34: =M17 -> 139.9 | J34: =N17 -> 50 | K34: =P17 -> 1197.94
A35: S | B35: 173 | D35: 32 | G35: 72 | H35: =M18 -> 170.4 | J35: =N18 -> 50 | K35: =P18 -> 1331.38
A36: O | B36: 173 | H36: =M19 -> 231.8 | J36: =N19 -> 50 | K36: =P19 -> 1546.28
A37: N | B37: 173 | E37: 8 | H37: =M20 -> 231.8 | J37: =N20 -> 50 | K37: =P20 -> 1546.28
A38: D | B38: 173 | D38: 40 | E38: 16 | H38: =M21 -> 231.8 | J38: =N21 -> 50 | K38: =P21 -> 1896.28
B39: =SUM(B27:B38) -> 2076 | C39: =SUM(C27:C38) -> 0 | D39: =SUM(D27:D38) -> 248 | E39: =SUM(E27:E38) -> 96 | F39: =SUM(F27:F38) -> 0 | G39: =SUM(G27:G38) -> 112 | H39: =SUM(H27:H38) -> 1994.4 | J39: =SUM(J27:J38) -> 600 | K39: =SUM(K27:K38) -> 16366.34

Sheet SANDRI Sandro
B2: LIVRE DE PAIE | D2: 2024 | F2: SALAIRES PLUS AVANCES MALADIE | L2: MATRICULE N° 1972 11 20 175 52
A4: Groupe Advensys Luxembourg SA
A5: Duarrefstrooss 49 | E5: Ancienneté | G5: =G6 -> 45566 | J5: D796015-2021 | L5: SANDRI Sandro | P5: N° 3
A6: L-9964 HULDANGE | E6: Entrée | G6: 45566 | L6: 24, Im Dahl
A7: 2015 22 06 748 | E7: Sortie | G7: 45535 | L7: L-9759 Knaphoscheid
A9: Jours | B9: Jours impos. | C9: Stat. | D9: Classe - % | E9: Rémun. Base | F9: Brut Mensuel | G9: Cotisable | H9: Maladie | I9: Pension | J9: CI-CO2 | K9: Déductions | L9: Imposable | M9: Impots | N9: CIS | O9: CISSM | P9: Salaire Net
A10: J 1-31 | B10: 25 | C10: Empl. | D10: 0.15 | E10: 13600 | F10: 13600 | G10: =F10 -> 13600 | H10: =380.8+34 -> 414.8 | I10: 1088 | J10: 0 | K10: =115.5+460 -> 575.5 | L10: 11521.7 | M10: 1728.26 | N10: 0 | O10: 0 | P10: 10131.54
A11: F 1-29 | B11: 25 | C11: Empl. | D11: 0.15 | E11: 16800 | F11: 16800 | G11: =F11 -> 16800 | H11: =470.4+42 -> 512.4 | I11: 1344 | J11: 0 | K11: =115.5+460 -> 575.5 | L11: 14368.1 | M11: 2155.22 | N11: 0 | O11: 0 | P11: 17610.87
A12: M 1-31 | B12: 25 | C12: Empl. | D12: 0.15 | E12: 19700 | F12: 19700 | G12: =F12 -> 19700 | H12: =551.6+49.25 -> 600.85 | I12: 1576 | J12: 0 | K12: =115.5+460 -> 575.5 | L12: 16947.65 | M12: 2542.15 | N12: 0 | O12: 0 | P12: 14840.2
A13: A 1-30 | B13: 25 | C13: Empl. | D13: 0.15 | E13: 8300 | F13: 8300 | G13: =F13 -> 8300 | H13: =232.4+20.75 -> 253.15 | I13: 664 | J13: 0 | K13: =115.5+460 -> 575.5 | L13: 6807.35 | M13: 1021.1 | N13: 0 | O13: 0 | P13: 12404.88
A14: M 1-31 | B14: 25 | C14: Empl. | D14: 2 | E14: 14500 | F14: 14500 | G14: =F14 -> 14500 | H14: =406+36.25 -> 442.25 | I14: 1160 | J14: 0 | K14: 115.5 | L14: 12782.25 | M14: 3248.9 | N14: 0 | O14: 0 | P14: 10974.45
A15: J 1-30 | B15: 25 | C15: Empl. | D15: 2 | E15: 12200 | F15: 12200 | G15: =F15 -> 12200 | H15: =341.6+30.5 -> 372.1 | I15: 976 | J15: 0 | K15: 115.5 | L15: 10736.4 | M15: 2395,,6 | N15: 0 | O15: 0 | P15: 12090.28
A16: J 1-31 | B16: 25 | C16: Empl. | D16: 2 | E16: 7000 | F16: 7000 | G16: =F16 -> 7000 | H16: =196+17.5 -> 213.5 | I16: 560 | J16: 0 | K16: 115.5 | L16: 6111 | M16: 642.9 | N16: 0 | O16: 0 | P16: 1941.2
A17: A 1-31 | B17: 25 | C17: Empl. | D17: 2 | E17: 7000 | F17: 7000 | G17: =F17 -> 7000 | H17: =196+17.5 -> 213.5 | I17: 560 | J17: 0 | K17: 115.5 | L17: 6111 | M17: 642.9 | N17: 0 | O17: 0 | P17: 5438.6
A18: S 1-30 | B18: 25 | C18: Empl. | D18: 2 | E18: 0 | F18: 0 | G18: =F18 -> 0 | H18: 0 | I18: 0 | J18: 0 | K18: 0 | L18: 0 | M18: 0 | N18: 0 | O18: 0 | P18: 0
A19: O 1-31 | B19: 25 | C19: Empl. | D19: 2 | E19: 0 | F19: 0 | G19: =F19 -> 0 | H19: 0 | I19: 0 | J19: 0 | K19: 0 | L19: 0 | M19: 0 | N19: 0 | O19: 0 | P19: 0
A20: N 1-30 | B20: 25 | C20: Empl. | D20: 2 | E20: 0 | F20: 0 | G20: =F20 -> 0 | H20: 0 | I20: 0 | J20: 0 | K20: 0 | L20: 0 | M20: 0 | N20: 0 | O20: 0 | P20: 0
A21: D 1-31 | B21: 25 | C21: Empl. | D21: 2 | E21: 0 | F21: 0 | G21: =F21 -> 0 | H21: 0 | I21: 0 | J21: 0 | K21: 0 | L21: 0 | M21: 0 | N21: 0 | O21: 0 | P21: 0
E22: =SUM(E10:E21) -> 99100 | F22: =SUM(F10:F21) -> 99100 | G22: =SUM(G10:G21) -> 99100 | H22: =SUM(H10:H21) -> 3022.55 | I22: =SUM(I10:I21) -> 7928 | J22: =SUM(J10:J21) -> 0 | K22: =SUM(K10:K21) -> 2764 | L22: =SUM(L10:L21) -> 85385.45 | ... P22: =SUM(P10:P21) -> 85432.02
A25: Heures | B25: Normal | C25: Suppl. | D25: Congés | E25: Férié extra | F25: Congés paternité | G25: Maladie | H25: RECAPITULATION ANNEE
H26: Imposable | J26: Impot | K26: NET
A27: J | B27: 173 | E27: 8 | H27: =M10 -> 1728.26 | J27: =N10 -> 0 | K27: =P10 -> 10131.54
A28: F | B28: 173 | H28: =M11 -> 2155.22 | J28: =N11 -> 0 | K28: =P11 -> 17610.87
A29: M | B29: 173 | H29: =M12 -> 2542.15 | J29: =N12 -> 0 | K29: =P12 -> 14840.2
A30: A | B30: 173 | E30: 8 | H30: =M13 -> 1021.1 | J30: =N13 -> 0 | K30: =P13 -> 12404.88
A31: M | B31: 173 | E31: 32 | H31: =M14 -> 3248.9 | J31: =N14 -> 0 | K31: =P14 -> 10974.45
A32: J | B32: 173 | E32: 8 | H32: =M15 -> 2395,,6 | J32: =N15 -> 0 | K32: =P15 -> 12090.28
A33: J | B33: 173 | H33: =M16 -> 642.9 | J33: =N16 -> 0 | K33: =P16 -> 1941.2
A34: A | B34: 173 | D34: 154.67 | E34: 8 | H34: =M17 -> 642.9 | J34: =N17 -> 0 | K34: =P17 -> 5438.6
A35: S | B35: - | H35: =M18 -> 0 | J35: =N18 -> 0 | K35: =P18 -> 0
A36: O | B36: - | H36: =M19 -> 0 | J36: =N19 -> 0 | K36: =P19 -> 0
A37: N | B37: - | H37: =M20 -> 0 | J37: =N20 -> 0 | K37: =P20 -> 0
A38: D | B38: - | H38: =M21 -> 0 | J38: =N21 -> 0 | K38: =P21 -> 0
B39: =SUM(B27:B38) -> 1384 | C39: =SUM(C27:C38) -> 0 | D39: =SUM(D27:D38) -> 154.67 | E39: =SUM(E27:E38) -> 64 | F39: =SUM(F27:F38) -> 0 | G39: =SUM(G27:G38) -> 0 | H39: =SUM(H27:H38) -> 11981.43 | J39: =SUM(J27:J38) -> 0 | K39: =SUM(K27:K38) -> 85432.02

Sheet JAUD Jean Paul
B2: LIVRE DE PAIE | D2: 2024 | F2: SALAIRES PLUS AVANCES MALADIE | L2: MATRICULE N° 1983 02 12 029 23
A4: Groupe Advensys Luxembourg SA
A5: Duarrefstrooss 49 | E5: Ancienneté | G5: =G6 -> 44502 | J5: - | L5: JAUD Jean Paul | P5: N° 4
A6: L-9964 HULDANGE | E6: Entrée | G6: 44502 | L6: 5, rue Jean Pierre Sauvage
A7: 2015 22 06 748 | E7: Sortie | L7: L-2514 Luxembourg
A9: Jours | B9: Jours impos. | C9: Stat. | D9: Classe - % | E9: Rémun. Base | F9: Brut Mensuel | G9: Cotisable | H9: Maladie | I9: Pension | J9: CI-CO2 | K9: Déductions | L9: Imposable | M9: Impots | N9: CIS | O9: CISSM | P9: Salaire Net
A10: J 1-31 | B10: 25 | C10: Empl. | D10: 2 | E10: 14100 | F10: 14100 | G10: =F10 -> 14100 | H10: =394.8+35.25 -> 430.05 | I10: 1128 | J10: 0 | K10: 0 | L10: 12541.95 | M10: 3148.7 | N10: 0 | O10: 0 | P10: 9148.85
A11: F 1-29 | B11: 25 | C11: Empl. | D11: 2 | E11: 9800 | F11: 9800 | G11: =F11 -> 9800 | H11: =274.4+24.5 -> 298.9 | I11: 784 | J11: 0 | K11: 0 | L11: 8717.1 | M11: 1552.6 | N11: 0 | O11: 0 | P11: 7272.28
A12: M 1-31 | B12: 25 | C12: Empl. | D12: 2 | E12: 12700 | F12: 12700 | G12: =F12 -> 12700 | H12: =355.6+31.75 -> 387.35 | I12: 1016 | J12: 0 | K12: 0 | L12: 11296.65 | M12: 2629.3 | N12: 0 | O12: 0 | P12: 3407.55
A13: A 1-30 | B13: 25 | C13: Empl. | D13: 2 | E13: 8800 | F13: 8800 | G13: =F13 -> 8800 | H13: =246.4+22 -> 268.4 | I13: 704 | J13: 0 | K13: 0 | L13: 7827.6 | M13: 1196.6 | N13: 0 | O13: 0 | P13: 6460.8
A14: M 1-31 | B14: 25 | C14: Empl. | D14: 2 | E14: 9500 | F14: 9500 | G14: =F14 -> 9500 | H14: =266+23.75 -> 289.75 | I14: 760 | J14: 0 | K14: 0 | L14: 8450.25 | M14: 1443.1 | N14: 0 | O14: 0 | P14: 6827.15
A15: J 1-30 | B15: 25 | C15: Empl. | D15: 2 | E15: 11400 | F15: 11400 | G15: =F15 -> 11400 | H15: =319.2+28.5 -> 347.7 | I15: 912 | J15: 0 | K15: 0 | L15: 10140.3 | M15: 2147.2 | N15: 0 | O15: 0 | P15: 7786.5
A16: J 1-31 | B16: 25 | C16: Empl. | D16: 2 | E16: 12600 | F16: 12600 | G16: =F16 -> 12600 | H16: =352.8+31.5 -> 384.3 | I16: 1008 | J16: 0 | K16: 0 | L16: 11207.7 | M16: 2591.7 | N16: 0 | O16: 0 | P16: 8392.6
A17: A 1-31 | B17: 25 | C17: Empl. | D17: 2 | E17: 6900 | F17: 6900 | G17: =F17 -> 6900 | H17: =193.2+17.25 -> 210.45 | I17: 552 | J17: 0 | K17: 0 | L17: 6137.55 | M17: 649.9 | N17: 0 | O17: 0 | P17: 5344.05
A18: S 1-30 | B18: 25 | C18: Empl. | D18: 2 | E18: 10800 | F18: 10800 | G18: =F18 -> 10800 | H18: =302.4+27 -> 329.4 | I18: 864 | J18: 0 | K18: 0 | L18: 9606.6 | M18: 1924 | N18: 0 | O18: 0 | P18: 7484.4
A19: O 1-31 | B19: 25 | C19: Empl. | D19: 2 | E19: 11000 | F19: 11000 | G19: =F19 -> 11000 | H19: =308+27.5 -> 335.5 | I19: 880 | J19: 0 | K19: 0 | L19: 9784.5 | M19: 1997 | N19: 0 | O19: 0 | P19: 7922.6
A20: N 1-30 | B20: 25 | C20: Empl. | D20: 2 | E20: 9200 | F20: 9200 | G20: =F20 -> 9200 | H20: =257.6+23 -> 280.6 | I20: 736 | J20: 0 | K20: 0 | L20: 8183.4 | M20: 1333.3 | N20: 0 | O20: 0 | P20: 6674.3
A21: D 1-31 | B21: 25 | C21: Empl. | D21: 2 | E21: 7300 | F21: 7300 | G21: =F21 -> 7300 | H21: =204.4+18.25 -> 222.65 | I21: 584 | J21: 0 | K21: 0 | L21: 6493.35 | M21: 750.8 | N21: 0 | O21: 0 | P21: 5891.23
E22: =SUM(E10:E21) -> 124100 | F22: =SUM(F10:F21) -> 124100 | G22: =SUM(G10:G21) -> 124100 | H22: =SUM(H10:H21) -> 3785.05 | I22: =SUM(I10:I21) -> 9928 | J22: =SUM(J10:J21) -> 0 | K22: =SUM(K10:K21) -> 0 | L22: =SUM(L10:L21) -> 110386.95 | ... P22: =SUM(P10:P21) -> 82612.31
A25: Heures | B25: Normal | C25: Suppl. | D25: Congés | E25: Férié extra | F25: Chômage | G25: Maladie | H25: RECAPITULATION ANNEE
H26: Imposable | J26: Impot | K26: NET
A27: J | B27: 173 | E27: 8 | H27: =M10 -> 3148.7 | J27: =N10 -> 0 | K27: =P10 -> 9148.85
A28: F | B28: 173 | H28: =M11 -> 1552.6 | J28: =N11 -> 0 | K28: =P11 -> 7272.28
A29: M | B29: 173 | H29: =M12 -> 2629.3 | J29: =N12 -> 0 | K29: =P12 -> 3407.55
A30: A | B30: 173 | E30: 8 | H30: =M13 -> 1196.6 | J30: =N13 -> 0 | K30: =P13 -> 6460.8
A31: M | B31: 173 | E31: 32 | H31: =M14 -> 1443.1 | J31: =N14 -> 0 | K31: =P14 -> 6827.15
A32: J | B32: 173 | E32: 8 | H32: =M15 -> 2147.2 | J32: =N15 -> 0 | K32: =P15 -> 7786.5
A33: J | B33: 173 | H33: =M16 -> 2591.7 | J33: =N16 -> 0 | K33: =P16 -> 8392.6
A34: A | B34: 173 | E34: 8 | H34: =M17 -> 649.9 | J34: =N17 -> 0 | K34: =P17 -> 5344.05
A35: S | B35: 173 | H35: =M18 -> 1924 | J35: =N18 -> 0 | K35: =P18 -> 7484.4
A36: O | B36: 173 | H36: =M19 -> 1997 | J36: =N19 -> 0 | K36: =P19 -> 7922.6
A37: N | B37: 173 | E37: 8 | H37: =M20 -> 1333.3 | J37: =N20 -> 0 | K37: =P20 -> 6674.3
A38: D | B38: 173 | E38: 16 | H38: =M21 -> 750.8 | J38: =N21 -> 0 | K38: =P21 -> 5891.23
B39: =SUM(B27:B38) -> 2076 | C39: =SUM(C27:C38) -> 0 | D39: =SUM(D27:D38) -> 0 | E39: =SUM(E27:E38) -> 88 | F39: =SUM(F27:F38) -> 0 | G39: =SUM(G27:G38) -> 0 | H39: =SUM(H27:H38) -> 21364.2 | J39: =SUM(J27:J38) -> 0 | K39: =SUM(K27:K38) -> 82612.31

Sheet REBELO MATOS Daniel Filipe
B2: LIVRE DE PAIE | D2: 2024 | F2: SALAIRES PLUS AVANCES MALADIE | L2: MATRICULE N° 2000 01 31 750 80
A4: Groupe Advensys Luxembourg SA
A5: Duarrefstrooss 49 | E5: Ancienneté | G5: =G6 -> 45173 | J5: D896475 | L5: REBELO MATOS Daniel Filipe | P5: N° 5
A6: L-9964 HULDANGE | E6: Entrée | G6: 45173 | L6: 6, rue de Kautenbach
A7: 2015 22 06 748 | E7: Sortie | L7: L-9831 Consthum
A9: Jours | B9: Jours impos. | C9: Stat. | D9: Classe - % | E9: Rémun. Base | F9: Brut Mensuel | G9: Cotisable | H9: Maladie | I9: Pension | J9: CI-CO2 | K9: Déductions | L9: Imposable | M9: Impots | N9: CIS | O9: CISSM | P9: Salaire Net
A10: J 1-31 | B10: 25 | C10: Empl. | D10: 1 | E10: 2570.93 | F10: 2570.93 | G10: =F10 -> 2570.93 | H10: =71.99+6.43 -> 78.42 | I10: 205.67 | J10: 14 | K10: 74.25 | L10: 2212.59 | M10: 135.8 | N10: 50 | O10: 70 | P10: 2640.04
A11: F 1-29 | B11: 25 | C11: Empl. | D11: 1 | E11: 2570.93 | F11: 2570.93 | G11: =F11 -> 2570.93 | H11: =71.99+6.43 -> 78.42 | I11: 205.67 | J11: 14 | K11: 74.25 | L11: 2212.59 | M11: 127.1 | N11: 50 | O11: 70 | P11: 2539.74
A12: M 1-31 | B12: 25 | C12: Empl. | D12: 1 | E12: 2570.93 | F12: 2570.93 | G12: =F12 -> 2570.93 | H12: =71.99+6.43 -> 78.42 | I12: 205.67 | J12: 14 | K12: 74.25 | L12: 2212.59 | M12: 127.1 | N12: 50 | O12: 70 | P12: 2533.74
A13: A 1-30 | B13: 25 | C13: Empl. | D13: 1 | E13: 2570.93 | F13: 2570.93 | G13: =F13 -> 2570.93 | H13: =71.99+6.43 -> 78.42 | I13: 205.67 | J13: 14 | K13: 74.25 | L13: 2212.59 | M13: 127.1 | N13: 50 | O13: 70 | P13: 2498.74
A14: M 1-31 | B14: 25 | C14: Empl. | D14: 1 | E14: 2570.93 | F14: 2570.93 | G14: =F14 -> 2570.93 | H14: =71.99+6.43 -> 78.42 | I14: 205.67 | J14: 14 | K14: 74.25 | L14: 2212.59 | M14: 127.1 | N14: 50 | O14: 70 | P14: 2533.74
A15: J 1-30 | B15: 25 | C15: Empl. | D15: 1 | E15: 2570.93 | F15: 2570.93 | G15: =F15 -> 2570.93 | H15: =71.99+6.43 -> 78.42 | I15: 205.67 | J15: 14 | K15: 74.25 | L15: 2212.59 | M15: 127.1 | N15: 50 | O15: 70 | P15: 2533.74
A16: J 1-31 | B16: 25 | C16: Empl. | D16: 1 | E16: 2570.93 | F16: 2570.93 | G16: =F16 -> 2570.93 | H16: =71.99+6.43 -> 78.42 | I16: 205.67 | J16: 14 | K16: 74.25 | L16: 2212.59 | M16: 127.1 | N16: 50 | O16: 70 | P16: 2837.74
A17: A 1-31 | B17: 25 | C17: Empl. | D17: 1 | E17: 2570.93 | F17: 2570.93 | G17: =F17 -> 2570.93 | H17: =71.99+6.43 -> 78.42 | I17: 205.67 | J17: 14 | K17: 74.25 | L17: 2212.59 | M17: 127.1 | N17: 50 | O17: 70 | P17: 2533.74
A18: S 1-30 | B18: 25 | C18: Empl. | D18: 1 | E18: 2570.93 | F18: 2570.93 | G18: =F18 -> 2570.93 | H18: =71.99+6.43 -> 78.42 | I18: 205.67 | J18: 14 | K18: 74.25 | L18: 2212.59 | M18: 127.1 | N18: 50 | O18: 70 | P18: 2533.74
A19: O 1-31 | B19: 25 | C19: Empl. | D19: 1 | E19: 2570.93 | F19: 2570.93 | G19: =F19 -> 2570.93 | H19: =71.99+6.43 -> 78.42 | I19: 205.67 | J19: 14 | K19: 74.25 | L19: 2212.59 | M19: 127.1 | N19: 50 | O19: 70 | P19: 2533.74
A20: N 1-30 | B20: 25 | C20: Empl. | D20: 1 | E20: 2570.93 | F20: 2570.93 | G20: =F20 -> 2570.93 | H20: =71.99+6.43 -> 78.42 | I20: 205.67 | J20: 14 | K20: 74.25 | L20: 2212.59 | M20: 127.1 | N20: 50 | O20: 70 | P20: 2608.74
A21: D 1-31 | B21: 25 | C21: Empl. | D21: 1 | E21: 2570.93 | F21: 2570.93 | G21: =F21 -> 2570.93 | H21: =71.99+6.43 -> 78.42 | I21: 205.67 | J21: 14 | K21: 74.25 | L21: 2212.59 | M21: 127.1 | N21: 50 | O21: 70 | P21: 2886.74
E22: =SUM(E10:E21) -> 30851.16 | F22: =SUM(F10:F21) -> 30851.16 | G22: =SUM(G10:G21) -> 30851.16 | H22: =SUM(H10:H21) -> 941.04 | I22: =SUM(I10:I21) -> 2468.04 | J22: =SUM(J10:J21) -> 168 | K22: =SUM(K10:K21) -> 891 | L22: =SUM(L10:L21) -> 26551.08 | ... P22: =SUM(P10:P21) -> 31214.18
A25: Heures | B25: Normal | C25: Suppl. | D25: Congés | E25: Férié extra | F25: Chômage | G25: Maladie | H25: RECAPITULATION ANNEE
H26: Imposable | J26: Impot | K26: NET
A27: J | B27: 173 | E27: 8 | G27: 16 | H27: =M10 -> 135.8 | J27: =N10 -> 50 | K27: =P10 -> 2640.04
A28: F | B28: 173 | D28: 32 | H28: =M11 -> 127.1 | J28: =N11 -> 50 | K28: =P11 -> 2539.74
A29: M | B29: 173 | G29: 8 | H29: =M12 -> 127.1 | J29: =N12 -> 50 | K29: =P12 -> 2533.74
A30: A | B30: 173 | D30: 16 | E30: 8 | H30: =M13 -> 127.1 | J30: =N13 -> 50 | K30: =P13 -> 2498.74
A31: M | B31: 173 | D31: 16 | E31: 32 | H31: =M14 -> 127.1 | J31: =N14 -> 50 | K31: =P14 -> 2533.74
A32: J | B32: 173 | D32: 7 | E32: 8 | H32: =M15 -> 127.1 | J32: =N15 -> 50 | K32: =P15 -> 2533.74
A33: J | B33: 173 | H33: =M16 -> 127.1 | J33: =N16 -> 50 | K33: =P16 -> 2837.74
A34: A | B34: 173 | D34: 132 | E34: 8 | G34: 1.5 | H34: =M17 -> 127.1 | J34: =N17 -> 50 | K34: =P17 -> 2533.74
A35: S | B35: 173 | H35: =M18 -> 127.1 | J35: =N18 -> 50 | K35: =P18 -> 2533.74
A36: O | B36: 173 | D36: 2.75 | H36: =M19 -> 127.1 | J36: =N19 -> 50 | K36: =P19 -> 2533.74
A37: N | B37: 173 | E37: 8 | H37: =M20 -> 127.1 | J37: =N20 -> 50 | K37: =P20 -> 2608.74
A38: D | B38: 173 | D38: 38 | E38: 16 | G38: 24 | H38: =M21 -> 127.1 | J38: =N21 -> 50 | K38: =P21 -> 2886.74
B39: =SUM(B27:B38) -> 2076 | C39: =SUM(C27:C38) -> 0 | D39: =SUM(D27:D38) -> 243.75 | E39: =SUM(E27:E38) -> 88 | F39: =SUM(F27:F38) -> 0 | G39: =SUM(G27:G38) -> 49.5 | H39: =SUM(H27:H38) -> 1533.9 | J39: =SUM(J27:J38) -> 600 | K39: =SUM(K27:K38) -> 31214.18

Sheet BALDE Binta
B2: LIVRE DE PAIE | D2: 2024 | F2: SALAIRES PLUS AVANCES MALADIE | L2: MATRICULE N° 2002 03 18 687 59
A4: Groupe Advensys Luxembourg SA
A5: Duarrefstrooss 49 | E5: Ancienneté | G5: =G6 -> 45446 | J5: D1124133-2024 | L5: BALDE Binta | P5: N° 6
A6: L-9964 HULDANGE | E6: Entrée | G6: 45446 | L6: 19A, Boulevard Konrad Adenauer
A7: 2015 22 06 748 | E7: Sortie | L7: L-1115 Luxembourg
A9: Jours | B9: Jours impos. | C9: Stat. | D9: Classe - % | E9: Rémun. Base | F9: Brut Mensuel | G9: Cotisable | H9: Maladie | I9: Pension | J9: CI-CO2 | K9: Déductions | L9: Imposable | M9: Impots | N9: CIS | O9: CISSM | P9: Salaire Net
A10: J 1-31 | B10: 25 | C10: Empl. | D10: 1 | E10: 0 | F10: 0 | G10: =F10 -> 0 | H10: 0 | I10: 0 | J10: 0 | K10: 0 | L10: 0 | M10: 0 | N10: 0 | O10: 0 | P10: 0
A11: F 1-29 | B11: 25 | C11: Empl. | D11: 1 | E11: 0 | F11: 0 | G11: =F11 -> 0 | H11: 0 | I11: 0 | J11: 0 | K11: 0 | L11: 0 | M11: 0 | N11: 0 | O11: 0 | P11: 0
A12: M 1-31 | B12: 25 | C12: Empl. | D12: 1 | E12: 0 | F12: 0 | G12: =F12 -> 0 | H12: 0 | I12: 0 | J12: 0 | K12: 0 | L12: 0 | M12: 0 | N12: 0 | O12: 0 | P12: 0
A13: A 1-30 | B13: 25 | C13: Empl. | D13: 1 | E13: 0 | F13: 0 | G13: =F13 -> 0 | H13: 0 | I13: 0 | J13: 0 | K13: 0 | L13: 0 | M13: 0 | N13: 0 | O13: 0 | P13: 0
A14: M 1-31 | B14: 25 | C14: Empl. | D14: 1 | E14: 0 | F14: 0 | G14: =F14 -> 0 | H14: 0 | I14: 0 | J14: 0 | K14: 0 | L14: 0 | M14: 0 | N14: 0 | O14: 0 | P14: 0
A15: J 1-30 | B15: 25 | C15: Empl. | D15: 1 | E15: 2570.93 | F15: 2570.93 | G15: =F15 -> 2570.93 | H15: =71.99+6.43 -> 78.42 | I15: 205.67 | J15: 14 | K15: 214.5 | L15: 2072.34 | M15: 105 | N15: 50 | O15: 70 | P15: 488.84
A16: J 1-31 | B16: 25 | C16: Empl. | D16: 1 | E16: 2570.93 | F16: 2570.93 | G16: =F16 -> 2570.93 | H16: =71.99+6.43 -> 78.42 | I16: 205.67 | J16: 14 | K16: 214.5 | L16: 2072.34 | M16: 105 | N16: 50 | O16: 70 | P16: 2589.84
A17: A 1-31 | B17: 25 | C17: Empl. | D17: 1 | E17: 2570.93 | F17: 2570.93 | G17: =F17 -> 2570.93 | H17: =71.99+6.43 -> 78.42 | I17: 205.67 | J17: 14 | K17: 214.5 | L17: 2072.34 | M17: 105 | N17: 50 | O17: 70 | P17: 2288.84
A18: S 1-30 | B18: 25 | C18: Empl. | D18: 1 | E18: 2570.93 | F18: 2570.93 | G18: =F18 -> 2570.93 | H18: =71.99+6.43 -> 78.42 | I18: 205.67 | J18: 14 | K18: 214.5 | L18: 2072.34 | M18: 105 | N18: 50 | O18: 70 | P18: 2348.17
A19: O 1-31 | B19: 25 | C19: Empl. | D19: 1 | E19: 2570.93 | F19: 2570.93 | G19: =F19 -> 2570.93 | H19: =71.99+6.43 -> 78.42 | I19: 205.67 | J19: 14 | K19: 214.5 | L19: 2072.34 | M19: 105 | N19: 50 | O19: 70 | P19: 2288.84
A20: N 1-30 | B20: 25 | C20: Empl. | D20: 1 | E20: 2570.93 | F20: 2570.93 | G20: =F20 -> 2570.93 | H20: =71.99+6.43 -> 78.42 | I20: 205.67 | J20: 14 | K20: 214.5 | L20: 2072.34 | M20: 105 | N20: 50 | O20: 70 | P20: 2288.84
A21: D 1-31 | B21: 25 | C21: Empl. | D21: 1 | E21: 2570.93 | F21: 2570.93 | G21: =F21 -> 2570.93 | H21: =71.99+6.43 -> 78.42 | I21: 205.67 | J21: 14 | K21: 214.5 | L21: 2072.34 | M21: 105 | N21: 50 | O21: 70 | P21: 2538.84
E22: =SUM(E10:E21) -> 17996.51 | F22: =SUM(F10:F21) -> 17996.51 | G22: =SUM(G10:G21) -> 17996.51 | H22: =SUM(H10:H21) -> 548.94 | I22: =SUM(I10:I21) -> 1439.69 | J22: =SUM(J10:J21) -> 98 | K22: =SUM(K10:K21) -> 1501.5 | L22: =SUM(L10:L21) -> 14506.38 | ... P22: =SUM(P10:P21) -> 14832.21
A25: Heures | B25: Normal | C25: Suppl. | D25: Congés | E25: Férié extra | F25: Chômage | G25: Maladie | H25: RECAPITULATION ANNEE
H26: Imposable | J26: Impot | K26: NET
A27: J | B27: - | H27: =M10 -> 0 | J27: =N10 -> 0 | K27: =P10 -> 0
A28: F | B28: - | H28: =M11 -> 0 | J28: =N11 -> 0 | K28: =P11 -> 0
A29: M | B29: - | H29: =M12 -> 0 | J29: =N12 -> 0 | K29: =P12 -> 0
A30: A | B30: - | H30: =M13 -> 0 | J30: =N13 -> 0 | K30: =P13 -> 0
A31: M | B31: - | H31: =M14 -> 0 | J31: =N14 -> 0 | K31: =P14 -> 0
A32: J | B32: 173 | D32: 8 | E32: 8 | H32: =M15 -> 105 | J32: =N15 -> 50 | K32: =P15 -> 488.84
A33: J | B33: 173 | D33: 16 | H33: =M16 -> 105 | J33: =N16 -> 50 | K33: =P16 -> 2589.84
A34: A | B34: 173 | D34: 80 | E34: 8 | H34: =M17 -> 105 | J34: =N17 -> 50 | K34: =P17 -> 2288.84
A35: S | B35: 173 | D35: 8 | H35: =M18 -> 105 | J35: =N18 -> 50 | K35: =P18 -> 2348.17
A36: O | B36: 173 | G36: 24 | H36: =M19 -> 105 | J36: =N19 -> 50 | K36: =P19 -> 2288.84
A37: N | B37: 173 | E37: 8 | H37: =M20 -> 105 | J37: =N20 -> 50 | K37: =P20 -> 2288.84
A38: D | B38: 173 | D38: 40 | E38: 16 | H38: =M21 -> 105 | J38: =N21 -> 50 | K38: =P21 -> 2538.84
B39: =SUM(B27:B38) -> 1211 | C39: =SUM(C27:C38) -> 0 | D39: =SUM(D27:D38) -> 152 | E39: =SUM(E27:E38) -> 40 | F39: =SUM(F27:F38) -> 0 | G39: =SUM(G27:G38) -> 24 | H39: =SUM(H27:H38) -> 735 | J39: =SUM(J27:J38) -> 350 | K39: =SUM(K27:K38) -> 14832.21

Sheet Omigie Evbaguehize Stella
B2: LIVRE DE PAIE | D2: 2024 | F2: SALAIRES PLUS AVANCES MALADIE | L2: MATRICULE N° 1984 01 24 046 29
A4: Groupe Advensys Luxembourg SA
A5: Duarrefstrooss 49 | E5: Ancienneté | G5: =G6 -> 45462 | J5: D1204976-2024 | L5: Omigie Evbaguehize Stella | P5: N° 7
A6: L-9964 HULDANGE | E6: Entrée | G6: 45462 | L6: 26, Hauptstrooss
A7: 2015 22 06 748 | E7: Sortie | L7: L-9972 LIELER
A9: Jours | B9: Jours impos. | C9: Stat. | D9: Classe - % | E9: Rémun. Base | F9: Brut Mensuel | G9: Cotisable | H9: Maladie | I9: Pension | J9: CI-CO2 | K9: Déductions | L9: Imposable | M9: Impots | N9: CIS | O9: CISSM | P9: Salaire Net
A10: J 1-31 | B10: 25 | C10: Empl. | D10: 1A | E10: 0 | F10: 0 | G10: =F10 -> 0 | H10: 0 | I10: 0 | J10: 0 | K10: 0 | L10: 0 | M10: 0 | N10: 0 | O10: 0 | P10: 0
A11: F 1-29 | B11: 25 | C11: Empl. | D11: 1A | E11: 0 | F11: 0 | G11: =F11 -> 0 | H11: 0 | I11: 0 | J11: 0 | K11: 0 | L11: 0 | M11: 0 | N11: 0 | O11: 0 | P11: 0
A12: M 1-31 | B12: 25 | C12: Empl. | D12: 1A | E12: 0 | F12: 0 | G12: =F12 -> 0 | H12: 0 | I12: 0 | J12: 0 | K12: 0 | L12: 0 | M12: 0 | N12: 0 | O12: 0 | P12: 0
A13: A 1-30 | B13: 25 | C13: Empl. | D13: 1A | E13: 0 | F13: 0 | G13: =F13 -> 0 | H13: 0 | I13: 0 | J13: 0 | K13: 0 | L13: 0 | M13: 0 | N13: 0 | O13: 0 | P13: 0
A14: M 1-31 | B14: 25 | C14: Empl. | D14: 1A | E14: 0 | F14: 0 | G14: =F14 -> 0 | H14: 0 | I14: 0 | J14: 0 | K14: 0 | L14: 0 | M14: 0 | N14: 0 | O14: 0 | P14: 0
A15: J 1-30 | B15: 25 | C15: Empl. | D15: 1A | E15: 951.1 | F15: 594.44 | G15: =F15 -> 594.44 | H15: =16.64+1.49 -> 18.13 | I15: 47.55 | J15: 14 | K15: 10.56 | L15: 518.19 | M15: 0 | N15: 39.98 | O15: 0 | P15: -916.6
A16: J 1-31 | B16: 25 | C16: Empl. | D16: 1A | E16: 297.22 | F16: 297.22 | G16: =F16 -> 297.22 | H16: =8.32+0.74 -> 9.06 | I16: 23.78 | J16: 14 | K16: 10.56 | L16: 253.82 | M16: 0 | N16: 31.36 | O16: 0 | P16: -852.03
A17: A 1-31 | B17: 25 | C17: Empl. | D17: 1A | E17: 297.22 | F17: 297.22 | G17: =F17 -> 297.22 | H17: =8.32+0.74 -> 9.06 | I17: 23.78 | J17: 14 | K17: 10.56 | L17: 253.82 | M17: 0 | N17: 31.36 | O17: 0 | P17: -537.46
A18: S 1-30 | B18: 25 | C18: Empl. | D18: 1A | E18: 297.22 | F18: 297.22 | G18: =F18 -> 297.22 | H18: =8.32+0.74 -> 9.06 | I18: 23.78 | J18: 14 | K18: 10.56 | L18: 253.82 | M18: 0 | N18: 31.36 | O18: 0 | P18: -572.89
A19: O 1-31 | B19: 25 | C19: Empl. | D19: 1A | E19: 297.22 | F19: 297.22 | G19: =F19 -> 297.22 | H19: =8.32+0.74 -> 9.06 | I19: 23.78 | J19: 14 | K19: 10.56 | L19: 253.82 | M19: 0 | N19: 31.36 | O19: 0 | P19: -258.32
A20: N 1-30 | B20: 25 | C20: Empl. | D20: 1A | E20: 297.22 | F20: 297.22 | G20: =F20 -> 297.22 | H20: =8.32+0.74 -> 9.06 | I20: 23.78 | J20: 14 | K20: 10.56 | L20: 253.82 | M20: 0 | N20: 31.36 | O20: 0 | P20: 56.25
A21: D 1-31 | B21: 25 | C21: Empl. | D21: 1A | E21: 297.22 | F21: 297.22 | G21: =F21 -> 297.22 | H21: =8.32+0.74 -> 9.06 | I21: 23.78 | J21: 14 | K21: 10.56 | L21: 253.82 | M21: 0 | N21: 31.36 | O21: 0 | P21: 314.57
E22: =SUM(E10:E21) -> 2734.42 | F22: =SUM(F10:F21) -> 2377.76 | G22: =SUM(G10:G21) -> 2377.76 | H22: =SUM(H10:H21) -> 72.49 | I22: =SUM(I10:I21) -> 190.23 | J22: =SUM(J10:J21) -> 98 | K22: =SUM(K10:K21) -> 73.92 | L22: =SUM(L10:L21) -> 2041.11 | ... P22: =SUM(P10:P21) -> -2766.48
A25: Heures | B25: Normal | C25: Suppl. | D25: Congés | E25: Férié extra | F25: Congés sans solde | G25: Maladie | H25: RECAPITULATION ANNEE
H26: Imposable | J26: Impot | K26: NET
A27: J | B27: - | H27: =M10 -> 0 | J27: =N10 -> 0 | K27: =P10 -> 0
A28: F | B28: - | H28: =M11 -> 0 | J28: =N11 -> 0 | K28: =P11 -> 0
A29: M | B29: - | H29: =M12 -> 0 | J29: =N12 -> 0 | K29: =P12 -> 0
A30: A | B30: - | H30: =M13 -> 0 | J30: =N13 -> 0 | K30: =P13 -> 0
A31: M | B31: - | H31: =M14 -> 0 | J31: =N14 -> 0 | K31: =P14 -> 0
A32: J | B32: 64 | F32: 24 | H32: =M15 -> 0 | J32: =N15 -> 39.98 | K32: =P15 -> -916.6
A33: J | B33: 20 | H33: =M16 -> 0 | J33: =N16 -> 31.36 | K33: =P16 -> -852.03
A34: A | B34: 20 | D34: 10 | E34: 5 | H34: =M17 -> 0 | J34: =N17 -> 31.36 | K34: =P17 -> -537.46
A35: S | B35: 20 | H35: =M18 -> 0 | J35: =N18 -> 31.36 | K35: =P18 -> -572.89
A36: O | B36: 20 | H36: =M19 -> 0 | J36: =N19 -> 31.36 | K36: =P19 -> -258.32
A37: N | B37: 20 | E37: 8 | H37: =M20 -> 0 | J37: =N20 -> 31.36 | K37: =P20 -> 56.25
A38: D | B38: 20 | E38: 16 | H38: =M21 -> 0 | J38: =N21 -> 31.36 | K38: =P21 -> 314.57
B39: =SUM(B27:B38) -> 184 | C39: =SUM(C27:C38) -> 0 | D39: =SUM(D27:D38) -> 10 | E39: =SUM(E27:E38) -> 29 | F39: =SUM(F27:F38) -> 24 | G39: =SUM(G27:G38) -> 0 | H39: =SUM(H27:H38) -> 0 | J39: =SUM(J27:J38) -> 228.14 | K39: =SUM(K27:K38) -> -2766.48

Sheet BEZGUBOV Tatiana
B2: LIVRE DE PAIE | D2: 2024 | F2: SALAIRES PLUS AVANCES MALADIE | L2: MATRICULE N° 1968 11 01 017 86
A4: Groupe Advensys Luxembourg SA
A5: Duarrefstrooss 49 | E5: Ancienneté | G5: =G6 -> 45323 | J5: D1029363-2024 | L5: BEZGUBOV Tatiana | P5: N° 6
A6: L-9964 HULDANGE | E6: Entrée | G6: 45323 | L6: 2a, rue Hannelast
A7: 2015 22 06 748 | E7: Sortie | G7: 45412 | L7: L-9544 WILTZ
A9: Jours | B9: Jours impos. | C9: Stat. | D9: Classe - % | E9: Rémun. Base | F9: Brut Mensuel | G9: Cotisable | H9: Maladie | I9: Pension | J9: CI-CO2 | K9: Déductions | L9: Imposable | M9: Impots | N9: CIS | O9: CISSM | P9: Salaire Net
A10: J 1-31 | B10: 25 | C10: Empl. | D10: 2 | E10: 0 | F10: 0 | G10: =F10 -> 0 | H10: 0 | I10: 0 | J10: 0 | K10: 0 | L10: 0 | M10: 0 | N10: 0 | O10: 0 | P10: 0
A11: F 1-29 | B11: 25 | C11: Empl. | D11: 2 | E11: 3085.11 | F11: 3085.11 | G11: =F11 -> 3085.11 | H11: =86.38+7.71 -> 94.09 | I11: 246.81 | J11: 14 | K11: 115.5 | L11: 2628.71 | M11: 41.1 | N11: 50 | O11: 60.07 | P11: 2792.98
A12: M 1-31 | B12: 25 | C12: Empl. | D12: 2 | E12: 3085.11 | F12: 3085.11 | G12: =F12 -> 3085.11 | H12: =86.38+7.71 -> 94.09 | I12: 246.81 | J12: 14 | K12: 115.5 | L12: 2628.71 | M12: 41.1 | N12: 50 | O12: 60.07 | P12: 2792.98
A13: A 1-30 | B13: 25 | C13: Empl. | D13: 2 | E13: 3085.11 | F13: 3085.11 | G13: =F13 -> 3085.11 | H13: =86.38+7.71 -> 94.09 | I13: 246.81 | J13: 14 | K13: 115.5 | L13: 2628.71 | M13: 41.1 | N13: 50 | O13: 60.07 | P13: 2757.98
A14: M 1-31 | B14: 25 | C14: Empl. | D14: 2 | E14: 0 | F14: 0 | G14: =F14 -> 0 | H14: 0 | I14: 0 | J14: 0 | K14: 0 | L14: 0 | M14: 0 | N14: 0 | O14: 0 | P14: 0
A15: J 1-30 | B15: 25 | C15: Empl. | D15: 2 | E15: 0 | F15: 0 | G15: =F15 -> 0 | H15: 0 | I15: 0 | J15: 0 | K15: 0 | L15: 0 | M15: 0 | N15: 0 | O15: 0 | P15: 0
A16: J 1-31 | B16: 25 | C16: Empl. | D16: 2 | E16: 0 | F16: 0 | G16: =F16 -> 0 | H16: 0 | I16: 0 | J16: 0 | K16: 0 | L16: 0 | M16: 0 | N16: 0 | O16: 0 | P16: 0
A17: A 1-31 | B17: 25 | C17: Empl. | D17: 2 | E17: 0 | F17: 0 | G17: =F17 -> 0 | H17: 0 | I17: 0 | J17: 0 | K17: 0 | L17: 0 | M17: 0 | N17: 0 | O17: 0 | P17: 0
A18: S 1-30 | B18: 25 | C18: Empl. | D18: 2 | E18: 0 | F18: 0 | G18: =F18 -> 0 | H18: 0 | I18: 0 | J18: 0 | K18: 0 | L18: 0 | M18: 0 | N18: 0 | O18: 0 | P18: 0
A19: O 1-31 | B19: 25 | C19: Empl. | D19: 2 | E19: 0 | F19: 0 | G19: =F19 -> 0 | H19: 0 | I19: 0 | J19: 0 | K19: 0 | L19: 0 | M19: 0 | N19: 0 | O19: 0 | P19: 0
A20: N 1-30 | B20: 25 | C20: Empl. | D20: 2 | E20: 0 | F20: 0 | G20: =F20 -> 0 | H20: 0 | I20: 0 | J20: 0 | K20: 0 | L20: 0 | M20: 0 | N20: 0 | O20: 0 | P20: 0
A21: D 1-31 | B21: 25 | C21: Empl. | D21: 2 | E21: 0 | F21: 0 | G21: =F21 -> 0 | H21: 0 | I21: 0 | J21: 0 | K21: 0 | L21: 0 | M21: 0 | N21: 0 | O21: 0 | P21: 0
E22: =SUM(E10:E21) -> 9255.33 | F22: =SUM(F10:F21) -> 9255.33 | G22: =SUM(G10:G21) -> 9255.33 | H22: =SUM(H10:H21) -> 282.27 | I22: =SUM(I10:I21) -> 740.43 | J22: =SUM(J10:J21) -> 42 | K22: =SUM(K10:K21) -> 346.5 | L22: =SUM(L10:L21) -> 7886.13 | ... P22: =SUM(P10:P21) -> 8343.94
A25: Heures | B25: Normal | C25: Suppl. | D25: Congés | E25: Férié extra | F25: Chômage | G25: Maladie | H25: RECAPITULATION ANNEE
H26: Imposable | J26: Impot | K26: NET
A27: J | B27: - | H27: =M10 -> 0 | J27: =N10 -> 0 | K27: =P10 -> 0
A28: F | B28: 173 | H28: =M11 -> 41.1 | J28: =N11 -> 50 | K28: =P11 -> 2792.98
A29: M | B29: 173 | H29: =M12 -> 41.1 | J29: =N12 -> 50 | K29: =P12 -> 2792.98
A30: A | B30: 173 | D30: 52 | E30: 8 | H30: =M13 -> 41.1 | J30: =N13 -> 50 | K30: =P13 -> 2757.98
A31: M | B31: - | H31: =M14 -> 0 | J31: =N14 -> 0 | K31: =P14 -> 0
A32: J | B32: - | H32: =M15 -> 0 | J32: =N15 -> 0 | K32: =P15 -> 0
A33: J | B33: - | H33: =M16 -> 0 | J33: =N16 -> 0 | K33: =P16 -> 0
A34: A | B34: - | H34: =M17 -> 0 | J34: =N17 -> 0 | K34: =P17 -> 0
A35: S | B35: - | H35: =M18 -> 0 | J35: =N18 -> 0 | K35: =P18 -> 0
A36: O | B36: - | H36: =M19 -> 0 | J36: =N19 -> 0 | K36: =P19 -> 0
A37: N | B37: - | H37: =M20 -> 0 | J37: =N20 -> 0 | K37: =P20 -> 0
A38: D | B38: - | H38: =M21 -> 0 | J38: =N21 -> 0 | K38: =P21 -> 0
B39: =SUM(B27:B38) -> 519 | C39: =SUM(C27:C38) -> 0 | D39: =SUM(D27:D38) -> 52 | E39: =SUM(E27:E38) -> 8 | F39: =SUM(F27:F38) -> 0 | G39: =SUM(G27:G38) -> 0 | H39: =SUM(H27:H38) -> 123.3 | J39: =SUM(J27:J38) -> 150 | K39: =SUM(K27:K38) -> 8343.94

Sheet RIFFAUD Jean François 
B2: LIVRE DE PAIE | D2: 2024 | F2: SALAIRES PLUS AVANCES MALADIE | L2: MATRICULE N° 1971 06 07 022 43
A4: Groupe Advensys Luxembourg SA
A5: Duarrefstrooss 49 | E5: Ancienneté | G5: =G6 -> 45337 | J5: D1029363-2024 | L5: RIFFAUD Jean François | P5: N° 7
A6: L-9964 HULDANGE | E6: Entrée | G6: 45337 | L6: 2a, rue Hannelast
A7: 2015 22 06 748 | E7: Sortie | G7: 45412 | L7: L-9544 WILTZ
A9: Jours | B9: Jours impos. | C9: Stat. | D9: Classe - % | E9: Rémun. Base | F9: Brut Mensuel | G9: Cotisable | H9: Maladie | I9: Pension | J9: CI-CO2 | K9: Déductions | L9: Imposable | M9: Impots | N9: CIS | O9: CISSM | P9: Salaire Net
A10: J 1-31 | B10: 25 | C10: Empl. | D10: 2-15% | E10: 0 | F10: 0 | G10: =F10 -> 0 | H10: 0 | I10: 0 | J10: 0 | K10: 0 | L10: 0 | M10: 0 | N10: 0 | O10: 0 | P10: 0
A11: F 1-29 | B11: 25 | C11: Empl. | D11: 2-15% | E11: 1569.3 | F11: 1569.3 | G11: =F11 -> 1569.3 | H11: =43.94+3.92 -> 47.86 | I11: 125.54 | J11: 14 | K11: =50.82+202.4 -> 253.22 | L11: 1142.68 | M11: 171.4 | N11: 50 | O11: 36.67 | P11: 1312.19
A12: M 1-31 | B12: 25 | C12: Empl. | D12: 2-15% | E12: 3085.11 | F12: 3085.11 | G12: =F12 -> 3085.11 | H12: =86.38+7.71 -> 94.09 | I12: 246.81 | J12: 14 | K12: =115.5+460 -> 575.5 | L12: 2628.71 | M12: 325.31 | N12: 50 | O12: 60.07 | P12: 2508.78
A13: A 1-30 | B13: 25 | C13: Empl. | D13: 2-15% | E13: 3085.11 | F13: 3085.11 | G13: =F13 -> 3085.11 | H13: =86.38+7.71 -> 94.09 | I13: 246.81 | J13: 14 | K13: =115.5+460 -> 575.5 | L13: 2628.71 | M13: 325.31 | N13: 50 | O13: 60.07 | P13: 2473.78
A14: M 1-31 | B14: 25 | C14: Empl. | D14: 2-15% | E14: 0 | F14: 0 | G14: =F14 -> 0 | H14: 0 | I14: 0 | J14: 0 | K14: 0 | L14: 0 | M14: 0 | N14: 0 | O14: 0 | P14: 0
A15: J 1-30 | B15: 25 | C15: Empl. | D15: 2-15% | E15: 0 | F15: 0 | G15: =F15 -> 0 | H15: 0 | I15: 0 | J15: 0 | K15: 0 | L15: 0 | M15: 0 | N15: 0 | O15: 0 | P15: 0
A16: J 1-31 | B16: 25 | C16: Empl. | D16: 2-15% | E16: 0 | F16: 0 | G16: =F16 -> 0 | H16: 0 | I16: 0 | J16: 0 | K16: 0 | L16: 0 | M16: 0 | N16: 0 | O16: 0 | P16: 0
A17: A 1-31 | B17: 25 | C17: Empl. | D17: 2-15% | E17: 0 | F17: 0 | G17: =F17 -> 0 | H17: 0 | I17: 0 | J17: 0 | K17: 0 | L17: 0 | M17: 0 | N17: 0 | O17: 0 | P17: 0
A18: S 1-30 | B18: 25 | C18: Empl. | D18: 2-15% | E18: 0 | F18: 0 | G18: =F18 -> 0 | H18: 0 | I18: 0 | J18: 0 | K18: 0 | L18: 0 | M18: 0 | N18: 0 | O18: 0 | P18: 0
A19: O 1-31 | B19: 25 | C19: Empl. | D19: 2-15% | E19: 0 | F19: 0 | G19: =F19 -> 0 | H19: 0 | I19: 0 | J19: 0 | K19: 0 | L19: 0 | M19: 0 | N19: 0 | O19: 0 | P19: 0
A20: N 1-30 | B20: 25 | C20: Empl. | D20: 2-15% | E20: 0 | F20: 0 | G20: =F20 -> 0 | H20: 0 | I20: 0 | J20: 0 | K20: 0 | L20: 0 | M20: 0 | N20: 0 | O20: 0 | P20: 0
A21: D 1-31 | B21: 25 | C21: Empl. | D21: 2-15% | E21: 0 | F21: 0 | G21: =F21 -> 0 | H21: 0 | I21: 0 | J21: 0 | K21: 0 | L21: 0 | M21: 0 | N21: 0 | O21: 0 | P21: 0
E22: =SUM(E10:E21) -> 7739.52 | F22: =SUM(F10:F21) -> 7739.52 | G22: =SUM(G10:G21) -> 7739.52 | H22: =SUM(H10:H21) -> 236.04 | I22: =SUM(I10:I21) -> 619.16 | J22: =SUM(J10:J21) -> 42 | K22: =SUM(K10:K21) -> 1404.22 | L22: =SUM(L10:L21) -> 6400.1 | ... P22: =SUM(P10:P21) -> 6294.75
A25: Heures | B25: Normal | C25: Suppl. | D25: Congés | E25: Férié extra | F25: Chômage | G25: Maladie | H25: RECAPITULATION ANNEE
H26: Imposable | J26: Impot | K26: NET
A27: J | B27: - | H27: =M10 -> 0 | J27: =N10 -> 0 | K27: =P10 -> 0
A28: F | B28: 88 | H28: =M11 -> 171.4 | J28: =N11 -> 50 | K28: =P11 -> 1312.19
A29: M | B29: 173 | H29: =M12 -> 325.31 | J29: =N12 -> 50 | K29: =P12 -> 2508.78
A30: A | B30: 173 | D30: 43.34 | E30: 8 | H30: =M13 -> 325.31 | J30: =N13 -> 50 | K30: =P13 -> 2473.78
A31: M | B31: - | H31: =M14 -> 0 | J31: =N14 -> 0 | K31: =P14 -> 0
A32: J | B32: - | H32: =M15 -> 0 | J32: =N15 -> 0 | K32: =P15 -> 0
A33: J | B33: - | H33: =M16 -> 0 | J33: =N16 -> 0 | K33: =P16 -> 0
A34: A | B34: - | H34: =M17 -> 0 | J34: =N17 -> 0 | K34: =P17 -> 0
A35: S | B35: - | H35: =M18 -> 0 | J35: =N18 -> 0 | K35: =P18 -> 0
A36: O | B36: - | H36: =M19 -> 0 | J36: =N19 -> 0 | K36: =P19 -> 0
A37: N | B37: - | H37: =M20 -> 0 | J37: =N20 -> 0 | K37: =P20 -> 0
A38: D | B38: - | H38: =M21 -> 0 | J38: =N21 -> 0 | K38: =P21 -> 0
B39: =SUM(B27:B38) -> 434 | C39: =SUM(C27:C38) -> 0 | D39: =SUM(D27:D38) -> 43.34 | E39: =SUM(E27:E38) -> 8 | F39: =SUM(F27:F38) -> 0 | G39: =SUM(G27:G38) -> 0 | H39: =SUM(H27:H38) -> 822.02 | J39: =SUM(J27:J38) -> 150 | K39: =SUM(K27:K38) -> 6294.75

Sheet BROERING Lucas José 
B2: LIVRE DE PAIE | D2: 2024 | F2: SALAIRES PLUS AVANCES MALADIE | L2: MATRICULE N° 1994 12 12 025 58
A4: Groupe Advensys Luxembourg SA
A5: Duarrefstrooss 49 | E5: Ancienneté | G5: =G6 -> 45383 | J5: D1196066-2024 | L5: BROERING Lucas José | P5: N° 8
A6: L-9964 HULDANGE | E6: Entrée | G6: 45383 | L6: 82, rue de Strasbourg
A7: 2015 22 06 748 | E7: Sortie | G7: 45427 | L7: L-2560 Luxembourg
A9: Jours | B9: Jours impos. | C9: Stat. | D9: Classe - % | E9: Rémun. Base | F9: Brut Mensuel | G9: Cotisable | H9: Maladie | I9: Pension | J9: CI-CO2 | K9: Déductions | L9: Imposable | M9: Impots | N9: CIS | O9: CISSM | P9: Salaire Net
A10: J 1-31 | B10: 25 | C10: Empl. | D10: 2 | E10: 0 | F10: 0 | G10: =F10 -> 0 | H10: 0 | I10: 0 | J10: 0 | K10: 0 | L10: 0 | M10: 0 | N10: 0 | O10: 0 | P10: 0
A11: F 1-28 | B11: 25 | C11: Empl. | D11: 2 | E11: 0 | F11: 0 | G11: =F11 -> 0 | H11: 0 | I11: 0 | J11: 0 | K11: 0 | L11: 0 | M11: 0 | N11: 0 | O11: 0 | P11: 0
A12: M 1-31 | B12: 25 | C12: Empl. | D12: 2 | E12: 0 | F12: 0 | G12: =F12 -> 0 | H12: 0 | I12: 0 | J12: 0 | K12: 0 | L12: 0 | M12: 0 | N12: 0 | O12: 0 | P12: 0
A13: A 1-30 | B13: 25 | C13: Empl. | D13: 2 | E13: 475.52 | F13: 451.74 | G13: =F13 -> 451.74 | H13: =12.65+1.13 -> 13.78 | I13: 36.14 | J13: 25 | K13: 214.5 | L13: 187.33 | M13: 0 | N13: 35.84 | O13: 0 | P13: 454.34
A14: M 1-31 | B14: 25 | C14: Empl. | D14: 2 | E14: 0 | F14: 0 | G14: =F14 -> 0 | H14: 0 | I14: 0 | J14: 0 | K14: 0 | L14: 0 | M14: 0 | N14: 0 | O14: 0 | P14: 0
A15: J 1-30 | B15: 25 | C15: Empl. | D15: 2 | E15: 0 | F15: 0 | G15: =F15 -> 0 | H15: 0 | I15: 0 | J15: 0 | K15: 0 | L15: 0 | M15: 0 | N15: 0 | O15: 0 | P15: 0
A16: J 1-31 | B16: 25 | C16: Empl. | D16: 2 | E16: 0 | F16: 0 | G16: =F16 -> 0 | H16: 0 | I16: 0 | J16: 0 | K16: 0 | L16: 0 | M16: 0 | N16: 0 | O16: 0 | P16: 0
A17: A 1-31 | B17: 25 | C17: Empl. | D17: 2 | E17: 0 | F17: 0 | G17: =F17 -> 0 | H17: 0 | I17: 0 | J17: 0 | K17: 0 | L17: 0 | M17: 0 | N17: 0 | O17: 0 | P17: 0
A18: S 1-30 | B18: 25 | C18: Empl. | D18: 2 | E18: 0 | F18: 0 | G18: =F18 -> 0 | H18: 0 | I18: 0 | J18: 0 | K18: 0 | L18: 0 | M18: 0 | N18: 0 | O18: 0 | P18: 0
A19: O 1-31 | B19: 25 | C19: Empl. | D19: 2 | E19: 0 | F19: 0 | G19: =F19 -> 0 | H19: 0 | I19: 0 | J19: 0 | K19: 0 | L19: 0 | M19: 0 | N19: 0 | O19: 0 | P19: 0
A20: N 1-30 | B20: 25 | C20: Empl. | D20: 2 | E20: 0 | F20: 0 | G20: =F20 -> 0 | H20: 0 | I20: 0 | J20: 0 | K20: 0 | L20: 0 | M20: 0 | N20: 0 | O20: 0 | P20: 0
A21: D 1-31 | B21: 25 | C21: Empl. | D21: 2 | E21: 0 | F21: 0 | G21: =F21 -> 0 | H21: 0 | I21: 0 | J21: 0 | K21: 0 | L21: 0 | M21: 0 | N21: 0 | O21: 0 | P21: 0
E22: =SUM(E10:E21) -> 475.52 | F22: =SUM(F10:F21) -> 451.74 | G22: =SUM(G10:G21) -> 451.74 | H22: =SUM(H10:H21) -> 13.78 | I22: =SUM(I10:I21) -> 36.14 | J22: =SUM(J10:J21) -> 25 | K22: =SUM(K10:K21) -> 214.5 | L22: =SUM(L10:L21) -> 187.33 | ... P22: =SUM(P10:P21) -> 454.34
A25: Heures | B25: Normal | C25: Suppl. | D25: Congés | E25: Férié extra | F25: Congés sans solde | G25: Maladie | H25: RECAPITULATION ANNEE
H26: Imposable | J26: Impot | K26: NET
A27: J | B27: - | H27: =M10 -> 0 | J27: =N10 -> 0 | K27: =P10 -> 0
A28: F | B28: - | H28: =M11 -> 0 | J28: =N11 -> 0 | K28: =P11 -> 0
A29: M | B29: - | H29: =M12 -> 0 | J29: =N12 -> 0 | K29: =P12 -> 0
A30: A | B30: 32 | D30: 5 | E30: 1.6 | F30: 1.6 | H30: =M13 -> 0 | J30: =N13 -> 35.84 | K30: =P13 -> 454.34
A31: M | B31: 16 | E31: 3.2 | F31: 16 | H31: =M14 -> 0 | J31: =N14 -> 0 | K31: =P14 -> 0
A32: J | B32: - | H32: =M15 -> 0 | J32: =N15 -> 0 | K32: =P15 -> 0
A33: J | B33: - | H33: =M16 -> 0 | J33: =N16 -> 0 | K33: =P16 -> 0
A34: A | B34: - | H34: =M17 -> 0 | J34: =N17 -> 0 | K34: =P17 -> 0
A35: S | B35: - | H35: =M18 -> 0 | J35: =N18 -> 0 | K35: =P18 -> 0
A36: O | B36: - | H36: =M19 -> 0 | J36: =N19 -> 0 | K36: =P19 -> 0
A37: N | B37: - | H37: =M20 -> 0 | J37: =N20 -> 0 | K37: =P20 -> 0
A38: D | B38: - | H38: =M21 -> 0 | J38: =N21 -> 0 | K38: =P21 -> 0
B39: =SUM(B27:B38) -> 48 | C39: =SUM(C27:C38) -> 0 | D39: =SUM(D27:D38) -> 5 | E39: =SUM(E27:E38) -> 4.8 | F39: =SUM(F27:F38) -> 17.6 | G39: =SUM(G27:G38) -> 0 | H39: =SUM(H27:H38) -> 0 | J39: =SUM(J27:J38) -> 35.84 | K39: =SUM(K27:K38) -> 454.34

Sheet Salaire globale +  Maladie
B2: LIVRE DE PAIE | D2: 2024 | F2: SALAIRES PLUS AVANCES MALADIE
A4: Groupe Advensys Luxembourg SA
A5: Duarrefstrooss 49
A6: L-9964 HULDANGE
A7: 20152206748
M8: RECAPITULATION ANNEE
A9: Mois | B9: Brut Mensuel | C9: Cotisable | D9: Maladie | E9: Pension | H9: Déductions | I9: Imposable | J9: Impôt | K9: Salaire Net | M9: Imposable | O9: Impôt | P9: Crédits
A10: JAN | B10: ='Miodrag MILIC'!F10+'BERTHE Alexandra'!F10+'SANDRI Sandro'!F10+'JAUD Jean Paul'!F10+'REBELO MATOS Daniel Filipe'!F10+'BALDE Binta'!F10+'Omigie Evbaguehize Stella'!F10+'BEZGUBOV Tatiana'!F10+'RIFFAUD Jean François '!F10+'BROERING Lucas José '!F10 -> 35412.795 | C10: ='Miodrag MILIC'!G10+'BERTHE Alexandra'!G10+'SANDRI Sandro'!G10+'JAUD Jean Paul'!G10+'REBELO MATOS Daniel Filipe'!G10+'BALDE Binta'!G10+'Omigie Evbaguehize Stella'!G10+'BEZGUBOV Tatiana'!G10+'RIFFAUD Jean François '!G10+'BROERING Lucas José '!G10 -> 35412.795 | D10: ='Miodrag MILIC'!H10+'BERTHE Alexandra'!H10+'SANDRI Sandro'!H10+'JAUD Jean Paul'!H10+'REBELO MATOS Daniel Filipe'!H10+'BALDE Binta'!H10+'Omigie Evbaguehize Stella'!H10+'BEZGUBOV Tatiana'!H10+'RIFFAUD Jean François '!H10+'BROERING Lucas José '!H10 -> 1080.11 | E10: ='Miodrag MILIC'!I10+'BERTHE Alexandra'!I10+'SANDRI Sandro'!I10+'JAUD Jean Paul'!I10+'REBELO MATOS Daniel Filipe'!I10+'BALDE Binta'!I10+'Omigie Evbaguehize Stella'!I10+'BEZGUBOV Tatiana'!I10+'RIFFAUD Jean François '!I10+'BROERING Lucas José '!I10 -> 2833.01 | H10: ='Miodrag MILIC'!K10+'BERTHE Alexandra'!K10+'SANDRI Sandro'!K10+'JAUD Jean Paul'!K10+'REBELO MATOS Daniel Filipe'!K10+'BALDE Binta'!K10+'Omigie Evbaguehize Stella'!K10+'BEZGUBOV Tatiana'!K10+'RIFFAUD Jean François '!K10+'BROERING Lucas José '!K10 -> 1142.75 | I10: ='Miodrag MILIC'!L10+'BERTHE Alexandra'!L10+'SANDRI Sandro'!L10+'JAUD Jean Paul'!L10+'REBELO MATOS Daniel Filipe'!L10+'BALDE Binta'!L10+'Omigie Evbaguehize Stella'!L10+'BEZGUBOV Tatiana'!L10+'RIFFAUD Jean François '!L10+'BROERING Lucas José '!L10 -> 30356.92 | J10: ='Miodrag MILIC'!M10+'BERTHE Alexandra'!M10+'SANDRI Sandro'!M10+'JAUD Jean Paul'!M10+'REBELO MATOS Daniel Filipe'!M10+'BALDE Binta'!M10+'Omigie Evbaguehize Stella'!M10+'BEZGUBOV Tatiana'!M10+'RIFFAUD Jean François '!M10+'BROERING Lucas José '!M10 -> 5431.14 | K10: ='Miodrag MILIC'!P10+'BERTHE Alexandra'!P10+'SANDRI Sandro'!P10+'JAUD Jean Paul'!P10+'REBELO MATOS Daniel Filipe'!P10+'BALDE Binta'!P10+'Omigie Evbaguehize Stella'!P10+'BEZGUBOV Tatiana'!P10+'RIFFAUD Jean François '!P10+'BROERING Lucas José '!P10 -> 25823.97 | M10: =I10 -> 30356.92 | O10: =J10 -> 5431.14 | P10: ='Miodrag MILIC'!J10+'Miodrag MILIC'!N10+'Miodrag MILIC'!O10+'BERTHE Alexandra'!J10+'BERTHE Alexandra'!N10+'BERTHE Alexandra'!O10+'REBELO MATOS Daniel Filipe'!J10+'REBELO MATOS Daniel Filipe'!N10+'REBELO MATOS Daniel Filipe'!O10+'BALDE Binta'!J10+'BALDE Binta'!N10+'BALDE Binta'!O10+'Omigie Evbaguehize Stella'!J10+'Omigie Evbaguehize Stella'!N10+'BEZGUBOV Tatiana'!J10+'BEZGUBOV Tatiana'!N10+'BEZGUBOV Tatiana'!O10+'RIFFAUD Jean François '!J10+'RIFFAUD Jean François '!N10+'RIFFAUD Jean François '!O10+'BROERING Lucas José '!J10+'BROERING Lucas José '!N10 -> 402
A11: FEV | B11: ='Miodrag MILIC'!F11+'BERTHE Alexandra'!F11+'SANDRI Sandro'!F11+'JAUD Jean Paul'!F11+'REBELO MATOS Daniel Filipe'!F11+'BALDE Binta'!F11+'Omigie Evbaguehize Stella'!F11+'BEZGUBOV Tatiana'!F11+'RIFFAUD Jean François '!F11+'BROERING Lucas José '!F11 -> 38967.205 | C11: ='Miodrag MILIC'!G11+'BERTHE Alexandra'!G11+'SANDRI Sandro'!G11+'JAUD Jean Paul'!G11+'REBELO MATOS Daniel Filipe'!G11+'BALDE Binta'!G11+'Omigie Evbaguehize Stella'!G11+'BEZGUBOV Tatiana'!G11+'RIFFAUD Jean François '!G11+'BROERING Lucas José '!G11 -> 38967.205 | D11: ='Miodrag MILIC'!H11+'BERTHE Alexandra'!H11+'SANDRI Sandro'!H11+'JAUD Jean Paul'!H11+'REBELO MATOS Daniel Filipe'!H11+'BALDE Binta'!H11+'Omigie Evbaguehize Stella'!H11+'BEZGUBOV Tatiana'!H11+'RIFFAUD Jean François '!H11+'BROERING Lucas José '!H11 -> 1188.51 | E11: ='Miodrag MILIC'!I11+'BERTHE Alexandra'!I11+'SANDRI Sandro'!I11+'JAUD Jean Paul'!I11+'REBELO MATOS Daniel Filipe'!I11+'BALDE Binta'!I11+'Omigie Evbaguehize Stella'!I11+'BEZGUBOV Tatiana'!I11+'RIFFAUD Jean François '!I11+'BROERING Lucas José '!I11 -> 3117.36 | H11: ='Miodrag MILIC'!K11+'BERTHE Alexandra'!K11+'SANDRI Sandro'!K11+'JAUD Jean Paul'!K11+'REBELO MATOS Daniel Filipe'!K11+'BALDE Binta'!K11+'Omigie Evbaguehize Stella'!K11+'BEZGUBOV Tatiana'!K11+'RIFFAUD Jean François '!K11+'BROERING Lucas José '!K11 -> 1511.47 | I11: ='Miodrag MILIC'!L11+'BERTHE Alexandra'!L11+'SANDRI Sandro'!L11+'JAUD Jean Paul'!L11+'REBELO MATOS Daniel Filipe'!L11+'BALDE Binta'!L11+'Omigie Evbaguehize Stella'!L11+'BEZGUBOV Tatiana'!L11+'RIFFAUD Jean François '!L11+'BROERING Lucas José '!L11 -> 33149.86 | J11: ='Miodrag MILIC'!M11+'BERTHE Alexandra'!M11+'SANDRI Sandro'!M11+'JAUD Jean Paul'!M11+'REBELO MATOS Daniel Filipe'!M11+'BALDE Binta'!M11+'Omigie Evbaguehize Stella'!M11+'BEZGUBOV Tatiana'!M11+'RIFFAUD Jean François '!M11+'BROERING Lucas José '!M11 -> 4455.82 | K11: ='Miodrag MILIC'!P11+'BERTHE Alexandra'!P11+'SANDRI Sandro'!P11+'JAUD Jean Paul'!P11+'REBELO MATOS Daniel Filipe'!P11+'BALDE Binta'!P11+'Omigie Evbaguehize Stella'!P11+'BEZGUBOV Tatiana'!P11+'RIFFAUD Jean François '!P11+'BROERING Lucas José '!P11 -> 35213.11 | M11: =I11 -> 33149.86 | O11: =J11 -> 4455.82 | P11: ='Miodrag MILIC'!J11+'Miodrag MILIC'!N11+'Miodrag MILIC'!O11+'BERTHE Alexandra'!J11+'BERTHE Alexandra'!N11+'BERTHE Alexandra'!O11+'REBELO MATOS Daniel Filipe'!J11+'REBELO MATOS Daniel Filipe'!N11+'REBELO MATOS Daniel Filipe'!O11+'BALDE Binta'!J11+'BALDE Binta'!N11+'BALDE Binta'!O11+'Omigie Evbaguehize Stella'!J11+'Omigie Evbaguehize Stella'!N11+'BEZGUBOV Tatiana'!J11+'BEZGUBOV Tatiana'!N11+'BEZGUBOV Tatiana'!O11+'RIFFAUD Jean François '!J11+'RIFFAUD Jean François '!N11+'RIFFAUD Jean François '!O11+'BROERING Lucas José '!J11+'BROERING Lucas José '!N11 -> 626.74
A12: MAR | B12: ='Miodrag MILIC'!F12+'BERTHE Alexandra'!F12+'SANDRI Sandro'!F12+'JAUD Jean Paul'!F12+'REBELO MATOS Daniel Filipe'!F12+'BALDE Binta'!F12+'Omigie Evbaguehize Stella'!F12+'BEZGUBOV Tatiana'!F12+'RIFFAUD Jean François '!F12+'BROERING Lucas José '!F12 -> 46283.015 | C12: ='Miodrag MILIC'!G12+'BERTHE Alexandra'!G12+'SANDRI Sandro'!G12+'JAUD Jean Paul'!G12+'REBELO MATOS Daniel Filipe'!G12+'BALDE Binta'!G12+'Omigie Evbaguehize Stella'!G12+'BEZGUBOV Tatiana'!G12+'RIFFAUD Jean François '!G12+'BROERING Lucas José '!G12 -> 46283.015 | D12: ='Miodrag MILIC'!H12+'BERTHE Alexandra'!H12+'SANDRI Sandro'!H12+'JAUD Jean Paul'!H12+'REBELO MATOS Daniel Filipe'!H12+'BALDE Binta'!H12+'Omigie Evbaguehize Stella'!H12+'BEZGUBOV Tatiana'!H12+'RIFFAUD Jean François '!H12+'BROERING Lucas José '!H12 -> 1411.64 | E12: ='Miodrag MILIC'!I12+'BERTHE Alexandra'!I12+'SANDRI Sandro'!I12+'JAUD Jean Paul'!I12+'REBELO MATOS Daniel Filipe'!I12+'BALDE Binta'!I12+'Omigie Evbaguehize Stella'!I12+'BEZGUBOV Tatiana'!I12+'RIFFAUD Jean François '!I12+'BROERING Lucas José '!I12 -> 3702.63 | H12: ='Miodrag MILIC'!K12+'BERTHE Alexandra'!K12+'SANDRI Sandro'!K12+'JAUD Jean Paul'!K12+'REBELO MATOS Daniel Filipe'!K12+'BALDE Binta'!K12+'Omigie Evbaguehize Stella'!K12+'BEZGUBOV Tatiana'!K12+'RIFFAUD Jean François '!K12+'BROERING Lucas José '!K12 -> 1833.75 | I12: ='Miodrag MILIC'!L12+'BERTHE Alexandra'!L12+'SANDRI Sandro'!L12+'JAUD Jean Paul'!L12+'REBELO MATOS Daniel Filipe'!L12+'BALDE Binta'!L12+'Omigie Evbaguehize Stella'!L12+'BEZGUBOV Tatiana'!L12+'RIFFAUD Jean François '!L12+'BROERING Lucas José '!L12 -> 39794.99 | J12: ='Miodrag MILIC'!M12+'BERTHE Alexandra'!M12+'SANDRI Sandro'!M12+'JAUD Jean Paul'!M12+'REBELO MATOS Daniel Filipe'!M12+'BALDE Binta'!M12+'Omigie Evbaguehize Stella'!M12+'BEZGUBOV Tatiana'!M12+'RIFFAUD Jean François '!M12+'BROERING Lucas José '!M12 -> 6073.36 | K12: ='Miodrag MILIC'!P12+'BERTHE Alexandra'!P12+'SANDRI Sandro'!P12+'JAUD Jean Paul'!P12+'REBELO MATOS Daniel Filipe'!P12+'BALDE Binta'!P12+'Omigie Evbaguehize Stella'!P12+'BEZGUBOV Tatiana'!P12+'RIFFAUD Jean François '!P12+'BROERING Lucas José '!P12 -> 29706.53 | M12: =I12 -> 39794.99 | O12: =J12 -> 6073.36 | P12: ='Miodrag MILIC'!J12+'Miodrag MILIC'!N12+'Miodrag MILIC'!O12+'BERTHE Alexandra'!J12+'BERTHE Alexandra'!N12+'BERTHE Alexandra'!O12+'REBELO MATOS Daniel Filipe'!J12+'REBELO MATOS Daniel Filipe'!N12+'REBELO MATOS Daniel Filipe'!O12+'BALDE Binta'!J12+'BALDE Binta'!N12+'BALDE Binta'!O12+'Omigie Evbaguehize Stella'!J12+'Omigie Evbaguehize Stella'!N12+'BEZGUBOV Tatiana'!J12+'BEZGUBOV Tatiana'!N12+'BEZGUBOV Tatiana'!O12+'RIFFAUD Jean François '!J12+'RIFFAUD Jean François '!N12+'RIFFAUD Jean François '!O12+'BROERING Lucas José '!J12+'BROERING Lucas José '!N12 -> 650.14
A13: AVR | B13: ='Miodrag MILIC'!F13+'BERTHE Alexandra'!F13+'SANDRI Sandro'!F13+'JAUD Jean Paul'!F13+'REBELO MATOS Daniel Filipe'!F13+'BALDE Binta'!F13+'Omigie Evbaguehize Stella'!F13+'BEZGUBOV Tatiana'!F13+'RIFFAUD Jean François '!F13+'BROERING Lucas José '!F13 -> 31434.755 | C13: ='Miodrag MILIC'!G13+'BERTHE Alexandra'!G13+'SANDRI Sandro'!G13+'JAUD Jean Paul'!G13+'REBELO MATOS Daniel Filipe'!G13+'BALDE Binta'!G13+'Omigie Evbaguehize Stella'!G13+'BEZGUBOV Tatiana'!G13+'RIFFAUD Jean François '!G13+'BROERING Lucas José '!G13 -> 31434.755 | D13: ='Miodrag MILIC'!H13+'BERTHE Alexandra'!H13+'SANDRI Sandro'!H13+'JAUD Jean Paul'!H13+'REBELO MATOS Daniel Filipe'!H13+'BALDE Binta'!H13+'Omigie Evbaguehize Stella'!H13+'BEZGUBOV Tatiana'!H13+'RIFFAUD Jean François '!H13+'BROERING Lucas José '!H13 -> 958.77 | E13: ='Miodrag MILIC'!I13+'BERTHE Alexandra'!I13+'SANDRI Sandro'!I13+'JAUD Jean Paul'!I13+'REBELO MATOS Daniel Filipe'!I13+'BALDE Binta'!I13+'Omigie Evbaguehize Stella'!I13+'BEZGUBOV Tatiana'!I13+'RIFFAUD Jean François '!I13+'BROERING Lucas José '!I13 -> 2514.77 | H13: ='Miodrag MILIC'!K13+'BERTHE Alexandra'!K13+'SANDRI Sandro'!K13+'JAUD Jean Paul'!K13+'REBELO MATOS Daniel Filipe'!K13+'BALDE Binta'!K13+'Omigie Evbaguehize Stella'!K13+'BEZGUBOV Tatiana'!K13+'RIFFAUD Jean François '!K13+'BROERING Lucas José '!K13 -> 2048.25 | I13: ='Miodrag MILIC'!L13+'BERTHE Alexandra'!L13+'SANDRI Sandro'!L13+'JAUD Jean Paul'!L13+'REBELO MATOS Daniel Filipe'!L13+'BALDE Binta'!L13+'Omigie Evbaguehize Stella'!L13+'BEZGUBOV Tatiana'!L13+'RIFFAUD Jean François '!L13+'BROERING Lucas José '!L13 -> 26372.97 | J13: ='Miodrag MILIC'!M13+'BERTHE Alexandra'!M13+'SANDRI Sandro'!M13+'JAUD Jean Paul'!M13+'REBELO MATOS Daniel Filipe'!M13+'BALDE Binta'!M13+'Omigie Evbaguehize Stella'!M13+'BEZGUBOV Tatiana'!M13+'RIFFAUD Jean François '!M13+'BROERING Lucas José '!M13 -> 3119.61 | K13: ='Miodrag MILIC'!P13+'BERTHE Alexandra'!P13+'SANDRI Sandro'!P13+'JAUD Jean Paul'!P13+'REBELO MATOS Daniel Filipe'!P13+'BALDE Binta'!P13+'Omigie Evbaguehize Stella'!P13+'BEZGUBOV Tatiana'!P13+'RIFFAUD Jean François '!P13+'BROERING Lucas José '!P13 -> 30478.8 | M13: =I13 -> 26372.97 | O13: =J13 -> 3119.61 | P13: ='Miodrag MILIC'!J13+'Miodrag MILIC'!N13+'Miodrag MILIC'!O13+'BERTHE Alexandra'!J13+'BERTHE Alexandra'!N13+'BERTHE Alexandra'!O13+'REBELO MATOS Daniel Filipe'!J13+'REBELO MATOS Daniel Filipe'!N13+'REBELO MATOS Daniel Filipe'!O13+'BALDE Binta'!J13+'BALDE Binta'!N13+'BALDE Binta'!O13+'Omigie Evbaguehize Stella'!J13+'Omigie Evbaguehize Stella'!N13+'BEZGUBOV Tatiana'!J13+'BEZGUBOV Tatiana'!N13+'BEZGUBOV Tatiana'!O13+'RIFFAUD Jean François '!J13+'RIFFAUD Jean François '!N13+'RIFFAUD Jean François '!O13+'BROERING Lucas José '!J13+'BROERING Lucas José '!N13 -> 710.98
