Workbook

Sheet janvier
A2: DECOMPTE SALAIRE/TRAITEMENT
A5: N° Salarié : | B5: 2 | F5: =[1]novembre!F5 -> Groupe Advensys Luxembourg S.A
A6: Indice : | B6: 21 | F6: =[1]novembre!F6 -> Duarrefstrooss 49
A7: Emploi : | B7: =[1]novembre!B7 -> Comptable | F7: =[1]novembre!F7 -> L-9964 Huldange
A8: Date d'entrée : | B8: =[1]novembre!B8 -> 44455
A9: Matricule assuré : | B9: =[1]novembre!B9 -> 1996 0905 124 86 | F9: =[1]novembre!F9 -> BERTHE Alexandra
A10: Matricule employeur : | B10: =[1]novembre!B10 -> 20152206748 | F10: =[1]novembre!F10 -> 93, Duarrefstrooss
A11: Période : | B11: Janvier 2025 | F11: =[1]novembre!F11 -> L-9964 Huldange
A12: Les montants sont exprimées en Euros.
A14: Désignation | B14: Quantité (heures) | C14: Valeur | D14: Total | F14: Cumuls M-1 | G14: Total
A16: Appointement | B16: =D49 -> 173 | C16: =D50 -> 18.296821 | D16: =B16*C16 -> 3165.35
A17: Jours fériée | B17: 0 | C17: 0 | D17: 0
A18: Congés (H) | B18: 16 | C18: 0 | D18: 0
A19: Absences Maladie (H) | B19: 0 | C19: 0 | D19: 0
A20: Total brut | D20: =D16+D19 -> 3165.35 | F20: 0 | G20: =D20+F20 -> 3165.35
A22: Cotisation
A23: Assurance Maladie | B23: 0.028 | D23: =D20*B23 -> 88.6298 | F23: 0 | G23: =D23 -> 88.6298
A24: A-M Majoration espèce | B24: 0.0025 | D24: =B24*D20 -> 7.913375 | F24: 0 | G24: =D24 -> 7.913375
A25: Assurance Pension | B25: 0.08 | D25: =B25*D20 -> 253.228 | F25: 0 | G25: =D25 -> 253.228
A26: Assurance dépendance | B26: 0.014 | D26: =B26*(D20-642.73) -> 35.31668 | F26: 0 | G26: =D26 -> 35.31668
A27: Total Cotisation | D27: =SUM(D23:D26) -> 385.08786 | F27: 0 | G27: =SUM(G23:G26) -> 385.08786
A29: Deduction | F29: 0 | G29: =D29 -> 0
A30: FD | D30: 0 | F30: 0 | G30: =D30 -> 0
A31: AC | D31: 0 | F31: 0 | G31: =D31 -> 0
A32: FFO | D32: 0 | F32: 0 | G32: =D32 -> 0
A33: FDS | D33: 0 | F33: 0 | G33: =D33 -> 0
A35: Total Imposable | D35: =D20-D23-D24-D25-D30-D31-D32-D33 -> 2815.5788 | F35: 0 | G35: =D35 -> 2815.5788
A37: IMPOT | D37: 225.3 | F37: 0 | G37: =D37 -> 225.3
A38: CISSM | D38: =IF(D20<1800,0,IF(D20<=3000,81,IF(D20>=3600,0,81/600*(3600-D20)))) -> 58.67775 | F38: 0 | G38: =D38 -> 58.67775
A39: CIS-CIP-CIM | D39: =IF(D20<78,0,IF(D20<936,((300+(D20*12-936)*0.029)/12),IF(D20<3333.33,50,IF(D20>6666.5,0,((600-(D20*12-40000)*0.015)/12))))) -> 50 | F39: 0 | G39: =D39 -> 50
A40: CI-CO2 | D40: =IF(D20<78,0,IF(D20<3333.33,16,IF(D20<6667,((16-(D20-3333.33)*0.0042)),0))) -> 16 | F40: 0 | G40: =D40 -> 16
A42: NET | D42: =D20-D27-D37+D38+D39+D40 -> 2679.6399 | F42: 0 | G42: =D42 -> 2679.6399
A43: Chéque repas | D43: 56
A44: Avance sur salaire | D44: 1000 | F44: NET A PAYER | G44: =D42-D44-D43 -> 1623.6399
A46: Congés (H)
A47: Légaux | B47: 208 | C47: Rémunération | F47: Fiche d'impôts
A48: Report | B48: -4 | C48: Salaire mensuel | D48: 3165.35 | F48: N° de carte | G48: D608388-2022
A49: Pris : | B49: =0+B18 -> 16 | C49: Heures | D49: 173 | F49: Classe | G49: 1
A50: Solde : | B50: =(B48+B47)-B49 -> 188 | C50: Salaire horaire | D50: =D48/D49 -> 18.296821 | F50: Taux | G50: -
A52: CONSERVEZ CE BULLETIN DE PAIE SANS LIMITATION DE DUREE

Sheet février
A2: DECOMPTE SALAIRE/TRAITEMENT
A5: N° Salarié : | B5: =janvier!B5 -> 2 | F5: =janvier!F5 -> Groupe Advensys Luxembourg S.A
A6: Indice : | B6: =janvier!B6 -> 21 | F6: =janvier!F6 -> Duarrefstrooss 49
A7: Emploi : | B7: =janvier!B7 -> Comptable | F7: =janvier!F7 -> L-9964 Huldange
A8: Date d'entrée : | B8: =janvier!B8 -> 44455
A9: Matricule assuré : | B9: =janvier!B9 -> 1996 0905 124 86 | F9: =janvier!F9 -> BERTHE Alexandra
A10: Matricule employeur : | B10: =janvier!B10 -> 20152206748 | F10: =janvier!F10 -> 93, Duarrefstrooss
A11: Période : | B11: Février 2024 | F11: =janvier!F11 -> L-9964 Huldange
A12: Les montants sont exprimées en Euros.
A14: Désignation | B14: Quantité (heures) | C14: Valeur | D14: Total | F14: Cumuls M-1 | G14: Total
A16: Appointement | B16: =D50 -> 173 | C16: =D51 -> 18.296821 | D16: =B16*C16 -> 3165.35
A17: Jours fériée | B17: 0 | C17: 0 | D17: 0
A18: Congés (H) | B18: 0 | C18: 0 | D18: 0
A19: Absences Maladie (H) | B19: 0 | C19: 0 | D19: 0
A20: Total brut | D20: =D16 -> 3165.35 | F20: =janvier!G20 -> 3165.35 | G20: =F20+D20 -> 6330.7
A22: Cotisation
A23: Assurance Maladie | B23: =janvier!B23 -> 0.028 | D23: =D20*B23 -> 88.6298 | F23: =janvier!G23 -> 88.6298 | G23: =F23+D23 -> 177.2596
A24: A-M Majoration espèce | B24: =janvier!B24 -> 0.0025 | D24: =B24*D20 -> 7.913375 | F24: =janvier!G24 -> 7.913375 | G24: =F24+D24 -> 15.82675
A25: Assurance Pension | B25: =janvier!B25 -> 0.08 | D25: =B25*D20 -> 253.228 | F25: =janvier!G25 -> 253.228 | G25: =F25+D25 -> 506.456
A26: Assurance dépendance | B26: =janvier!B26 -> 0.014 | D26: =B26*(D20-659.45) -> 35.0826 | F26: =janvier!G26 -> 35.31668 | G26: =F26+D26 -> 70.39928
A27: Total Cotisation | D27: =SUM(D23:D26) -> 384.85378 | F27: =janvier!G27 -> 385.08786 | G27: =F27+D27 -> 769.94163
A29: Deduction
A30: FD | D30: =janvier!D30 -> 0 | F30: =janvier!G30 -> 0 | G30: =F30+D30 -> 0
A31: AC | D31: =janvier!D31 -> 0 | F31: =janvier!G31 -> 0 | G31: =F31+D31 -> 0
A32: FFO | D32: =janvier!D32 -> 0 | F32: =janvier!G32 -> 0 | G32: =F32+D32 -> 0
A33: FDS | D33: =janvier!D33 -> 0 | F33: =janvier!G33 -> 0 | G33: =F33+D33 -> 0
A35: Total Imposable | D35: =D20-D23-D24-D25-D30-D31-D32-D33 -> 2815.5788 | F35: =janvier!G35 -> 2815.5788 | G35: =F35+D35 -> 5631.1576
A37: IMPOT | D37: =janvier!D37 -> 225.3 | F37: =janvier!G37 -> 225.3 | G37: =F37+D37 -> 450.6
A38: CISSM | D38: =IF(D20<1800,0,IF(D20<=3000,81,IF(D20>=3600,0,81/600*(3600-D20)))) -> 58.67775 | F38: =janvier!G38+7.97 -> 66.64775 | G38: =F38+D38 -> 125.3255
A39: CIS-CIP-CIM | D39: =IF(D20<78,0,IF(D20<936,((300+(D20*12-936)*0.029)/12),IF(D20<3333.33,50,IF(D20>6666.5,0,((600-(D20*12-40000)*0.015)/12))))) -> 50 | F39: =janvier!G39 -> 50 | G39: =F39+D39 -> 100
A40: CI-CO2 | D40: =IF(D20<78,0,IF(D20<3333.33,16,IF(D20<6667,((16-(D20-3333.33)*0.0042)),0))) -> 16 | F40: =janvier!G40+2 -> 18 | G40: =D40+F40 -> 34
A42: NET | D42: =D20-D27-D37+D38+D39+D40 -> 2679.874 | F42: =janvier!G42 -> 2679.6399 | G42: =F42+D42 -> 5359.5139
A43: Chéque repas | D43: 56
A44: Avance sur salaire | D44: 1700 | F44: NET A PAYER | G44: =D42-D43-D44+D45 -> 933.84397
A45: Rectif CISSM/CO | D45: 9.97
A47: Congés (H)
A48: Légaux | B48: =janvier!B47 -> 208 | C48: Rémunération | F48: Fiche d'impôts
A49: Report | B49: =janvier!B48 -> -4 | C49: Salaire mensuel | D49: =D50*D51 -> 3165.35 | F49: N° de carte | G49: =janvier!G48 -> D608388-2022
A50: Pris : | B50: =janvier!B49+B18 -> 16 | C50: Heures | D50: =janvier!D49 -> 173 | F50: Classe | G50: =janvier!G49 -> 1
A51: Solde : | B51: =(B49+B48)-B50 -> 188 | C51: Salaire horaire | D51: =janvier!D50 -> 18.296821 | F51: Taux | G51: =janvier!G50 -> -
...

Sheet mars
A2: DECOMPTE SALAIRE/TRAITEMENT
A5: N° Salarié : | B5: =février!B5 -> 2 | F5: =février!F5 -> Groupe Advensys Luxembourg S.A
A6: Indice : | B6: =février!B6 -> 21 | F6: =février!F6 -> Duarrefstrooss 49
A7: Emploi : | B7: =février!B7 -> Comptable | F7: =février!F7 -> L-9964 Huldange
A8: Date d'entrée : | B8: =février!B8 -> 44455
A9: Matricule assuré : | B9: =février!B9 -> 1996 0905 124 86 | F9: =février!F9 -> BERTHE Alexandra
A10: Matricule employeur : | B10: =février!B10 -> 20152206748 | F10: =février!F10 -> 93, Duarrefstrooss
A11: Période : | B11: Mars 2024 | F11: =février!F11 -> L-9964 Huldange
A12: Les montants sont exprimées en Euros.
A14: Désignation | B14: Quantité (heures) | C14: Valeur | D14: Total | F14: Cumuls M-1 | G14: Total
A16: Appointement | B16: =D49 -> 173 | C16: =D50 -> 18.296821 | D16: =B16*C16 -> 3165.35
A17: Jours fériée | B17: 0 | C17: 0 | D17: 0
A18: Congés (H) | B18: 0 | C18: 0 | D18: 0
A19: Absences Maladie (H) | B19: 24 | C19: 0 | D19: 0
A20: Total brut | D20: =D16 -> 3165.35 | F20: =février!G20 -> 6330.7 | G20: =F20+D20 -> 9496.05
A22: Cotisation
A23: Assurance Maladie | B23: =février!B23 -> 0.028 | D23: =D20*B23 -> 88.6298 | F23: =février!G23 -> 177.2596 | G23: =F23+D23 -> 265.8894
A24: A-M Majoration espèce | B24: =février!B24 -> 0.0025 | D24: =B24*D20 -> 7.913375 | F24: =février!G24 -> 15.82675 | G24: =F24+D24 -> 23.740125
A25: Assurance Pension | B25: =février!B25 -> 0.08 | D25: =B25*D20 -> 253.228 | F25: =février!G25 -> 506.456 | G25: =F25+D25 -> 759.684
A26: Assurance dépendance | B26: =février!B26 -> 0.014 | D26: =B26*(D20-642.73) -> 35.31668 | F26: =février!G26 -> 70.39928 | G26: =F26+D26 -> 105.71596
A27: Total Cotisation | D27: =SUM(D23:D26) -> 385.08786 | F27: =février!G27 -> 769.94163 | G27: =F27+D27 -> 1155.0295
A29: Deduction
A30: FD | D30: =février!D30 -> 0 | F30: =février!G30 -> 0 | G30: =F30+D30 -> 0
A31: AC | D31: =février!D31 -> 0 | F31: =février!G31 -> 0 | G31: =F31+D31 -> 0
A32: FFO | D32: =février!D32 -> 0 | F32: =février!G32 -> 0 | G32: =F32+D32 -> 0
A33: FDS | D33: =février!D33 -> 0 | F33: =février!G33 -> 0 | G33: =F33+D33 -> 0
A35: Total Imposable | D35: =D20-D23-D24-D25-D30-D31-D32-D33 -> 2815.5788 | F35: =février!G35 -> 5631.1576 | G35: =F35+D35 -> 8446.7365
A37: IMPOT | D37: =février!D37 -> 225.3 | F37: =février!G37 -> 450.6 | G37: =F37+D37 -> 675.9
A38: CISSM | D38: =IF(D20<1800,0,IF(D20<=3000,81,IF(D20>=3600,0,81/600*(3600-D20)))) -> 58.67775 | F38: =février!G38 -> 125.3255 | G38: =F38+D38 -> 184.00325
A39: CIS-CIP-CIM | D39: =IF(D20<78,0,IF(D20<936,((300+(D20*12-936)*0.029)/12),IF(D20<3333.33,50,IF(D20>6666.5,0,((600-(D20*12-40000)*0.015)/12))))) -> 50 | F39: =février!G39 -> 100 | G39: =F39+D39 -> 150
A40: CI-CO2 | D40: =IF(D20<78,0,IF(D20<3333.33,16,IF(D20<6667,((16-(D20-3333.33)*0.0042)),0))) -> 16 | F40: =février!G40 -> 34 | G40: =F40+D40 -> 50
A42: NET | D42: =D20-D27-D37+D38+D39+D40 -> 2679.6399 | F42: =février!G42 -> 5359.5139 | G42: =F42+D42 -> 8039.1538
A44: Chéque repas | D44: 56 | F44: NET A PAYER | G44: =D42-D44-D45 -> 1423.6399
A45: Avance sur salaire | D45: 1200
A47: Congés (H) | C47: Rémunération | F47: Fiche d'impôts
A48: Légaux | B48: =février!B48 -> 208 | C48: Salaire mensuel | D48: =D49*D50 -> 3165.35 | F48: N° de carte | G48: =février!G49 -> D608388-2022
A49: Report | B49: =février!B49 -> -4 | C49: Heures | D49: =février!D50 -> 173 | F49: Classe | G49: =février!G50 -> 1
A50: Pris : | B50: =février!B50+B18 -> 16 | C50: Salaire horaire | D50: =février!D51 -> 18.296821 | F50: Taux | G50: =février!G51 -> -
A51: Solde : | B51: =(B49+B48)-B50 -> 188
A52: CONSERVEZ CE BULLETIN DE PAIE SANS LIMITATION DE DUREE

Sheet Avril
A2: DECOMPTE SALAIRE/TRAITEMENT
A5: N° Salarié : | B5: =mars!B5 -> 2 | F5: =mars!F5 -> Groupe Advensys Luxembourg S.A
A6: Indice : | B6: =mars!B6 -> 21 | F6: =mars!F6 -> Duarrefstrooss 49
A7: Emploi : | B7: =mars!B7 -> Comptable | F7: =mars!F7 -> L-9964 Huldange
A8: Date d'entrée : | B8: =mars!B8 -> 44455
A9: Matricule assuré : | B9: =mars!B9 -> 1996 0905 124 86 | F9: =mars!F9 -> BERTHE Alexandra
A10: Matricule employeur : | B10: =mars!B10 -> 20152206748 | F10: =mars!F10 -> 93, Duarrefstrooss
A11: Période : | B11: Avril 2024 | F11: =mars!F11 -> L-9964 Huldange
A12: Les montants sont exprimées en Euros.
A14: Désignation | B14: Quantité (heures) | C14: Valeur | D14: Total | F14: Cumuls M-1 | G14: Total
A16: Appointement | B16: =D51 -> 173 | C16: =D52 -> 18.296821 | D16: =D50 -> 3165.35
A17: Jours fériée | B17: 8 | C17: 0 | D17: 0
A18: Congés (H) | B18: 9
A19: Absences Maladie (H) | B19: 0
A20: Total brut | D20: =D16 -> 3165.35 | F20: =mars!G20 -> 9496.05 | G20: =F20+D20 -> 12661.4
A22: Cotisation
A23: Assurance Maladie | B23: =mars!B23 -> 0.028 | D23: =D20*B23 -> 88.6298 | F23: =mars!G23 -> 265.8894 | G23: =F23+D23 -> 354.5192
A24: A-M Majoration espèce | B24: =mars!B24 -> 0.0025 | D24: =B24*D20 -> 7.913375 | F24: =mars!G24 -> 23.740125 | G24: =F24+D24 -> 31.6535
A25: Assurance Pension | B25: =mars!B25 -> 0.08 | D25: =B25*D20 -> 253.228 | F25: =mars!G25 -> 759.684 | G25: =F25+D25 -> 1012.912
A26: Assurance dépendance | B26: =mars!B26 -> 0.014 | D26: =B26*(D20-642.73) -> 35.31668 | F26: =mars!G26 -> 105.71596 | G26: =F26+D26 -> 141.03264
A27: Total Cotisation | D27: =SUM(D23:D26) -> 385.08786 | F27: =mars!G27 -> 1155.0295 | G27: =F27+D27 -> 1540.1173
A29: Deduction
A30: FD | D30: =mars!D30 -> 0 | F30: =mars!G30 -> 0 | G30: =F30+D30 -> 0
A31: AC | D31: =mars!D31 -> 0 | F31: =mars!G31 -> 0 | G31: =F31+D31 -> 0
A32: FFO | D32: =mars!D32 -> 0 | F32: =mars!G32 -> 0 | G32: =F32+D32 -> 0
A33: FDS | D33: =mars!D33 -> 0 | F33: =mars!G33 -> 0 | G33: =F33+D33 -> 0
A35: Total Imposable | D35: =D20-D23-D24-D25-D30-D31-D32-D33 -> 2815.5788 | F35: =mars!G35 -> 8446.7365 | G35: =F35+D35 -> 11262.315
A37: IMPOT | D37: =février!D37 -> 225.3 | F37: =mars!G37 -> 675.9 | G37: =F37+D37 -> 901.2
A38: CISSM | D38: =IF(D20<1800,0,IF(D20<=3000,81,IF(D20>=3600,0,81/600*(3600-D20)))) -> 58.67775 | F38: =mars!G38 -> 184.00325 | G38: =F38+D38 -> 242.681
A39: CIS-CIP-CIM | D39: =IF(D20<78,0,IF(D20<936,((300+(D20*12-936)*0.029)/12),IF(D20<3333.33,50,IF(D20>6666.5,0,((600-(D20*12-40000)*0.015)/12))))) -> 50 | F39: =mars!G39 -> 150 | G39: =F39+D39 -> 200
A40: CI-CO2 | D40: =IF(D20<78,0,IF(D20<3333.33,16,IF(D20<6667,((16-(D20-3333.33)*0.0042)),0))) -> 16 | F40: =mars!G40 -> 50 | G40: =F40+D40 -> 66
A42: NET | D42: =D20-D27-D37+D38+D39+D40 -> 2679.6399 | F42: =mars!G42 -> 8039.1538 | G42: =F42+D42 -> 10718.794
A43: Chéque repas | D43: 56
A44: Avance sur salaire | D44: 1200 | F44: NET A PAYER | G44: =D42-D43-D44-D45+D46 -> 1408.5799
A45: Cotisation chambre des salariés | D45: 35
A46: Rectif credit d'impots mars + avril | D46: =9.97*2 -> 19.94
A48: Congés (H)
A49: Légaux | B49: =mars!B48 -> 208 | C49: Rémunération | F49: Fiche d'impôts
A50: Report | B50: =mars!B49 -> -4 | C50: Salaire mensuel | D50: =D51*D52 -> 3165.35 | F50: N° de carte | G50: =mars!G48 -> D608388-2022
A51: Pris : | B51: =mars!B50+B18 -> 25 | C51: Heures | D51: =mars!D49 -> 173 | F51: Classe | G51: =mars!G49 -> 1
...

Sheet mai
A2: DECOMPTE SALAIRE/TRAITEMENT
A5: N° Salarié : | B5: =Avril!B5 -> 2 | F5: =Avril!F5 -> Groupe Advensys Luxembourg S.A
A6: Indice : | B6: 968,04 | F6: =Avril!F6 -> Duarrefstrooss 49
A7: Emploi : | B7: =Avril!B7 -> Comptable | F7: =Avril!F7 -> L-9964 Huldange
A8: Date d'entrée : | B8: =Avril!B8 -> 44455
A9: Matricule assuré : | B9: =Avril!B9 -> 1996 0905 124 86 | F9: =Avril!F9 -> BERTHE Alexandra
A10: Matricule employeur : | B10: =Avril!B10 -> 20152206748 | F10: =Avril!F10 -> 93, Duarrefstrooss
A11: Période : | B11: Mai 2024 | F11: =Avril!F11 -> L-9964 Huldange
A12: Les montants sont exprimées en Euros.
A14: Désignation | B14: Quantité (heures) | C14: Valeur | D14: Total | F14: Cumuls M-1 | G14: Total
A16: Appointement | B16: =D49 -> 173 | C16: =D50 -> 18.753757 | D16: 3244.4
A17: Jours fériée | B17: =8*3 -> 24 | C17: 0 | D17: 0
A18: Congés (H) | B18: 0 | C18: 0 | D18: 0
A19: Absences Maladie (H) | B19: 0 | D19: 0
A20: Total brut | D20: =D16 -> 3244.4 | F20: =Avril!G20 -> 12661.4 | G20: =F20+D20 -> 15905.8
A22: Cotisation
A23: Assurance Maladie | B23: =Avril!B23 -> 0.028 | D23: =D20*B23 -> 90.8432 | F23: =Avril!G23 -> 354.5192 | G23: =F23+D23 -> 445.3624
A24: A-M Majoration espèce | B24: =Avril!B24 -> 0.0025 | D24: =B24*D20 -> 8.111 | F24: =Avril!G24 -> 31.6535 | G24: =F24+D24 -> 39.7645
A25: Assurance Pension | B25: =Avril!B25 -> 0.08 | D25: =B25*D20 -> 259.552 | F25: =Avril!G25 -> 1012.912 | G25: =F25+D25 -> 1272.464
A26: Assurance dépendance | B26: =Avril!B26 -> 0.014 | D26: =B26*(D20-675.93) -> 35.95858 | F26: =Avril!G26 -> 141.03264 | G26: =F26+D26 -> 176.99122
A27: Total Cotisation | D27: =SUM(D23:D26) -> 394.46478 | F27: =Avril!G27 -> 1540.1173 | G27: =F27+D27 -> 1934.5821
A29: Deduction
A30: FD | D30: =Avril!D30 -> 0 | F30: =Avril!G30 -> 0 | G30: =F30+D30 -> 0
A31: AC | D31: =Avril!D31 -> 0 | F31: =Avril!G31 -> 0 | G31: =F31+D31 -> 0
A32: FFO | D32: =Avril!D32 -> 0 | F32: =Avril!G32 -> 0 | G32: =F32+D32 -> 0
A33: FDS | D33: =Avril!D33 -> 0 | F33: =Avril!G33 -> 0 | G33: =F33+D33 -> 0
A35: Total Imposable | D35: =D20-D23-D24-D25-D30-D31-D32-D33 -> 2885.8938 | F35: =Avril!G35 -> 11262.315 | G35: =F35+D35 -> 14148.209
A37: IMPOT | D37: 240.6 | F37: =Avril!G37 -> 901.2 | G37: =F37+D37 -> 1141.8
A38: CISSM | D38: =IF(D20<1800,0,IF(D20<=3000,81,IF(D20>=3600,0,81/600*(3600-D20)))) -> 48.006 | F38: =Avril!G38 -> 242.681 | G38: =F38+D38 -> 290.687
A39: CIS-CIP-CIM | D39: =IF(D20<78,0,IF(D20<936,((300+(D20*12-936)*0.029)/12),IF(D20<3333.33,50,IF(D20>6666.5,0,((600-(D20*12-40000)*0.015)/12))))) -> 50 | F39: =Avril!G39 -> 200 | G39: =F39+D39 -> 250
A40: CI-CO2 | D40: =IF(D20<78,0,IF(D20<3333.33,16,IF(D20<6667,((16-(D20-3333.33)*0.0042)),0))) -> 16 | F40: =Avril!G40 -> 66 | G40: =F40+D40 -> 82
A42: NET | D42: =D20-D27-D37+D38+D39+D40 -> 2723.3412 | F42: =Avril!G42 -> 10718.794 | G42: =F42+D42 -> 13442.135
A43: Chéque repas | D43: 56
A44: Avance sur salaire | D44: 1000 | F44: NET A PAYER | G44: =D42-D43-D44 -> 1667.3412
A46: Congés (H)
A47: Légaux | B47: =Avril!B49 -> 208 | C47: Rémunération | F47: Fiche d'impôts
A48: Report | B48: =Avril!B50 -> -4 | C48: Salaire mensuel | D48: 3244.4 | F48: N° de carte | G48: =Avril!G50 -> D608388-2022
A49: Pris : | B49: =Avril!B51+B18 -> 25 | C49: Heures | D49: =Avril!D51 -> 173 | F49: Classe | G49: =Avril!G51 -> 1
A50: Solde : | B50: =(B48+B47)-B49 -> 179 | C50: Salaire horaire | D50: =D48/D49 -> 18.753757 | F50: Taux | G50: =Avril!G52 -> -
A52: CONSERVEZ CE BULLETIN DE PAIE SANS LIMITATION DE DUREE

Sheet juin
A2: DECOMPTE SALAIRE/TRAITEMENT
A5: N° Salarié : | B5: =mai!B5 -> 2 | F5: =mai!F5 -> Groupe Advensys Luxembourg S.A
A6: Indice : | B6: =mai!B6 -> 968,04 | F6: =mai!F6 -> Duarrefstrooss 49
A7: Emploi : | B7: =mai!B7 -> Comptable | F7: =mai!F7 -> L-9964 Huldange
A8: Date d'entrée : | B8: =mai!B8 -> 44455
A9: Matricule assuré : | B9: =mai!B9 -> 1996 0905 124 86 | F9: =mai!F9 -> BERTHE Alexandra
A10: Matricule employeur : | B10: =mai!B10 -> 20152206748 | F10: =mai!F10 -> 93, Duarrefstrooss
A11: Période : | B11: Juin 2025 | F11: =mai!F11 -> L-9964 Huldange
A12: Les montants sont exprimées en Euros.
A14: Désignation | B14: Quantité (heures) | C14: Valeur | D14: Total | F14: Cumuls M-1 | G14: Total
A16: Appointement | B16: =D49 -> 173 | C16: =D50 -> 18.753757 | D16: =B16*C16 -> 3244.4
A17: Jours fériée | B17: 16 | C17: 0 | D17: 0
A18: Congés (H) | B18: =9*8 -> 72 | C18: 0 | D18: 0
A19: Absences Maladie (H)
A20: Total brut | D20: =D16 -> 3244.4 | F20: =mai!G20 -> 15905.8 | G20: =F20+D20 -> 19150.2
A22: Cotisation
A23: Assurance Maladie | B23: =mai!B23 -> 0.028 | D23: =D20*B23 -> 90.8432 | F23: =mai!G23 -> 445.3624 | G23: =F23+D23 -> 536.2056
A24: A-M Majoration espèce | B24: =mai!B24 -> 0.0025 | D24: =B24*D20 -> 8.111 | F24: =mai!G24 -> 39.7645 | G24: =F24+D24 -> 47.8755
A25: Assurance Pension | B25: =mai!B25 -> 0.08 | D25: =B25*D20 -> 259.552 | F25: =mai!G25 -> 1272.464 | G25: =F25+D25 -> 1532.016
A26: Assurance dépendance | B26: =mai!B26 -> 0.014 | D26: =B26*(D20-675.93) -> 35.95858 | F26: =mai!G26 -> 176.99122 | G26: =F26+D26 -> 212.9498
A27: Total Cotisation | D27: =SUM(D23:D26) -> 394.46478 | F27: =mai!G27 -> 1934.5821 | G27: =F27+D27 -> 2329.0469
A29: Deduction
A30: FD | D30: =mai!D30 -> 0 | F30: =mai!G30 -> 0 | G30: =F30+D30 -> 0
A31: AC | D31: =mai!D31 -> 0 | F31: =mai!G31 -> 0 | G31: =F31+D31 -> 0
A32: FFO | D32: =mai!D32 -> 0 | F32: =mai!G32 -> 0 | G32: =F32+D32 -> 0
A33: FDS | D33: =mai!D33 -> 0 | F33: =mai!G33 -> 0 | G33: =F33+D33 -> 0
A35: Total Imposable | D35: =D20-D23-D24-D25-D30-D31-D32-D33 -> 2885.8938 | F35: =mai!G35 -> 14148.209 | G35: =F35+D35 -> 17034.103
A37: IMPOT | D37: 240.6 | F37: =mai!G37 -> 1141.8 | G37: =F37+D37 -> 1382.4
A38: CISSM | D38: =IF(D20<1800,0,IF(D20<=3000,81,IF(D20>=3600,0,81/600*(3600-D20)))) -> 48.006 | F38: =mai!G38 -> 290.687 | G38: =F38+D38 -> 338.693
A39: CIS-CIP-CIM | D39: =IF(D20<78,0,IF(D20<936,((300+(D20*12-936)*0.029)/12),IF(D20<3333.33,50,IF(D20>6666.5,0,((600-(D20*12-40000)*0.015)/12))))) -> 50 | F39: =mai!G39 -> 250 | G39: =F39+D39 -> 300
A40: CI-CO2 | D40: =IF(D20<78,0,IF(D20<3333.33,16,IF(D20<6667,((16-(D20-3333.33)*0.0042)),0))) -> 16 | F40: =mai!G40 -> 82 | G40: =F40+D40 -> 98
A42: NET | D42: =D20-D27-D37+D38+D39+D40 -> 2723.3412 | F42: =mai!G42 -> 13442.135 | G42: =F42+D42 -> 16165.476
A43: Chéque repas | D43: 56
A44: Avance sur salaire | D44: 1000 | F44: NET A PAYER | G44: =D42-D43-D44 -> 1667.3412
A46: Congés (H)
A47: Légaux | B47: =mai!B47 -> 208 | C47: Rémunération | F47: Fiche d'impôts
A48: Report | B48: =mai!B48 -> -4 | C48: Salaire mensuel | D48: =D49*D50 -> 3244.4 | F48: N° de carte | G48: =mai!G48 -> D608388-2022
A49: Pris : | B49: =mai!B49+B18 -> 97 | C49: Heures | D49: =mai!D49 -> 173 | F49: Classe | G49: =mai!G49 -> 1
A50: Solde : | B50: =(B48+B47)-B49 -> 107 | C50: Salaire horaire | D50: =mai!D50 -> 18.753757 | F50: Taux | G50: =mai!G50 -> -
A52: CONSERVEZ CE BULLETIN DE PAIE SANS LIMITATION DE DUREE

Sheet juillet
A2: DECOMPTE SALAIRE/TRAITEMENT
A5: N° Salarié : | B5: =juin!B5 -> 2 | F5: =juin!F5 -> Groupe Advensys Luxembourg S.A
A6: Indice : | B6: =juin!B6 -> 968,04 | F6: =juin!F6 -> Duarrefstrooss 49
A7: Emploi : | B7: =juin!B7 -> Comptable | F7: =juin!F7 -> L-9964 Huldange
A8: Date d'entrée : | B8: =juin!B8 -> 44455
A9: Matricule assuré : | B9: =juin!B9 -> 1996 0905 124 86 | F9: =juin!F9 -> BERTHE Alexandra
A10: Matricule employeur : | B10: =juin!B10 -> 20152206748 | F10: =juin!F10 -> 93, Duarrefstrooss
A11: Période : | B11: Juillet 2025 | F11: =juin!F11 -> L-9964 Huldange
A12: Les montants sont exprimées en Euros.
A14: Désignation | B14: Quantité (heures) | C14: Valeur | D14: Total | F14: Cumuls M-1 | G14: Total
A16: Appointement | B16: =D52 -> 173 | C16: =D53 -> 18.753757 | D16: =B16*C16 -> 3244.4
A17: Jours fériée | B17: 0 | C17: 0 | D17: 0
A18: Congés (H) | B18: 0 | C18: 0 | D18: 0
A19: Heures Suppl. (H) | B19: 19.42 | C19: =C16 -> 18.753757 | D19: =B19*C19 -> 364.19797 | F19: =juin!G17 -> 0 | G19: =F19+D19+D20 -> 509.87715
A20: H-S part majorée 40% (H) | B20: 19.42 | C20: =C19*0.4 -> 7.5015029 | D20: =C20*B20 -> 145.67919
A21: Absences Maladie (H) | B21: 0 | C21: 0 | D21: 0
A22: Total brut | D22: =D16 -> 3244.4 | F22: =juin!G20 -> 19150.2 | G22: =F22+D22 -> 22394.6
A24: Cotisation
A25: Assurance Maladie | B25: =juin!B23 -> 0.028 | D25: =(D19+D22)*B25 -> 101.04074 | F25: =juin!G23 -> 536.2056 | G25: =F25+D25 -> 637.24634
A26: A-M Majoration espèce | B26: =juin!B24 -> 0.0025 | D26: =B26*D22 -> 8.111 | F26: =juin!G24 -> 47.8755 | G26: =F26+D26 -> 55.9865
A27: Assurance Pension | B27: =juin!B25 -> 0.08 | D27: =B27*D22 -> 259.552 | F27: =juin!G25 -> 1532.016 | G27: =F27+D27 -> 1791.568
A28: Assurance dépendance | B28: =juin!B26 -> 0.014 | D28: =B28*(D19+D22-675.93) -> 41.057352 | F28: =juin!G26 -> 212.9498 | G28: =F28+D28 -> 254.00715
A29: Total Cotisation | D29: =SUM(D25:D28) -> 409.76109 | F29: =juin!G27 -> 2329.0469 | G29: =F29+D29 -> 2738.808
A31: Deduction
A32: FD | D32: =juin!D30 -> 0 | F32: =juin!G30 -> 0 | G32: =F32+D32 -> 0
A33: AC | D33: =juin!D31 -> 0 | F33: =juin!G31 -> 0 | G33: =F33+D33 -> 0
A34: FFO | D34: =juin!D32 -> 0 | F34: =juin!G32 -> 0 | G34: =F34+D34 -> 0
A35: FDS | D35: =juin!D33 -> 0 | F35: =juin!G33 -> 0 | G35: =F35+D35 -> 0
A37: Total Imposable | D37: =D22-D25-D26-D27-D32-D33-D34-D35 -> 2875.6963 | F37: =juin!G35 -> 17034.103 | G37: =F37+D37 -> 19909.799
A39: IMPOT | D39: 240.6 | F39: =juin!G37 -> 1382.4 | G39: =F39+D39 -> 1623
A40: CISSM | D40: =IF(D22<1800,0,IF(D22<=3000,81,IF(D22>=3600,0,81/600*(3600-D22)))) -> 48.006 | F40: =juin!G38 -> 338.693 | G40: =F40+D40 -> 386.699
A41: CIS-CIP-CIM | D41: =IF(D22<78,0,IF(D22<936,((300+(D22*12-936)*0.029)/12),IF(D22<3333.33,50,IF(D22>6666.5,0,((600-(D22*12-40000)*0.015)/12))))) -> 50 | F41: =juin!G39 -> 300 | G41: =F41+D41 -> 350
A42: CI-CO2 | D42: =IF(D22<78,0,IF(D22<3333.33,16,IF(D22<6667,((16-(D22-3333.33)*0.0042)),0))) -> 16 | F42: =juin!G40 -> 98 | G42: =F42+D42 -> 114
A44: NET | D44: =D22-D29-D39+D40+D41+D42+D19+D20 -> 3217.9221 | F44: =juin!G42 -> 16165.476 | G44: =F44+D44 -> 19383.398
A45: Chéque repas | D45: 56
A46: Avance sur salaire | D46: 1400 | F46: NET A PAYER | G46: =D44-D45-D46+D47 -> 2463.6221
A47: Frais kilometrique | D47: 701.7
A49: Congés (H)
A50: Légaux | B50: =+juin!B47 -> 208 | C50: Rémunération | F50: Fiche d'impôts
A51: Report | B51: =+juin!B48 -> -4 | C51: Salaire mensuel | D51: =D52*D53 -> 3244.4 | F51: N° de carte | G51: =juin!G48 -> D608388-2022
...

Sheet aout
A2: DECOMPTE SALAIRE/TRAITEMENT
A5: N° Salarié : | B5: =juillet!B5 -> 2 | F5: =juillet!F5 -> Groupe Advensys Luxembourg S.A
A6: Indice : | B6: =juillet!B6 -> 968,04 | F6: =juillet!F6 -> Duarrefstrooss 49
A7: Emploi : | B7: =juillet!B7 -> Comptable | F7: =juillet!F7 -> L-9964 Huldange
A8: Date d'entrée : | B8: =juillet!B8 -> 44455
A9: Matricule assuré : | B9: =juillet!B9 -> 1996 0905 124 86 | F9: =juillet!F9 -> BERTHE Alexandra
A10: Matricule employeur : | B10: =juillet!B10 -> 20152206748 | F10: =juillet!F10 -> 93, Duarrefstrooss
A11: Période : | B11: Aout 2025 | F11: =juillet!F11 -> L-9964 Huldange
A12: Les montants sont exprimées en Euros.
A14: Désignation | B14: Quantité (heures) | C14: Valeur | D14: Total | F14: Cumuls M-1 | G14: Total
A16: Appointement | B16: =D51 -> 173 | C16: =D52 -> 18.753757 | D16: =B16*C16 -> 3244.4
A17: Jours fériée | B17: 8 | C17: 0 | D17: 0
A18: Congés (H) | B18: 0 | C18: 0 | D18: 0
A19: Absences Maladie (H)
A20: Total brut | D20: =D16 -> 3244.4 | F20: =juillet!G22 -> 22394.6 | G20: =F20+D20 -> 25639
A22: Cotisation
A23: Assurance Maladie | B23: =juillet!B25 -> 0.028 | D23: =D20*B23 -> 90.8432 | F23: =juillet!G25 -> 637.24634 | G23: =F23+D23 -> 728.08954
A24: A-M Majoration espèce | B24: =juillet!B26 -> 0.0025 | D24: =B24*D20 -> 8.111 | F24: =juillet!G26 -> 55.9865 | G24: =F24+D24 -> 64.0975
A25: Assurance Pension | B25: =juillet!B27 -> 0.08 | D25: =B25*D20 -> 259.552 | F25: =juillet!G27 -> 1791.568 | G25: =F25+D25 -> 2051.12
A26: Assurance dépendance | B26: =juillet!B28 -> 0.014 | D26: =B26*(D17+D20-675.93) -> 35.95858 | F26: =juillet!G28 -> 254.00715 | G26: =F26+D26 -> 289.96573
A27: Total Cotisation | D27: =SUM(D23:D26) -> 394.46478 | F27: =juillet!G29 -> 2738.808 | G27: =F27+D27 -> 3133.2728
A29: Deduction
A30: FD | D30: =juillet!D32 -> 0 | F30: =juillet!G32 -> 0 | G30: =F30+D30 -> 0
A31: AC | D31: =juillet!D33 -> 0 | F31: =juillet!G33 -> 0 | G31: =F31+D31 -> 0
A32: FFO | D32: =juillet!D34 -> 0 | F32: =juillet!G34 -> 0 | G32: =F32+D32 -> 0
A33: FDS | D33: =juillet!D35 -> 0 | F33: =juillet!G35 -> 0 | G33: =F33+D33 -> 0
A35: Total Imposable | D35: =D20-D23-D24-D25-D30-D31-D32-D33 -> 2885.8938 | F35: =juillet!G37 -> 19909.799 | G35: =F35+D35 -> 22795.693
A37: IMPOT | D37: 240.6 | F37: =juillet!G39 -> 1623 | G37: =F37+D37 -> 1863.6
A38: CISSM | D38: =IF(D20<1800,0,IF(D20<=3000,81,IF(D20>=3600,0,81/600*(3600-D20)))) -> 48.006 | F38: =juillet!G40 -> 386.699 | G38: =F38+D38 -> 434.705
A39: CIS-CIP-CIM | D39: =IF(D20<78,0,IF(D20<936,((300+(D20*12-936)*0.029)/12),IF(D20<3333.33,50,IF(D20>6666.5,0,((600-(D20*12-40000)*0.015)/12))))) -> 50 | F39: =juillet!G41 -> 350 | G39: =F39+D39 -> 400
A40: CI-CO2 | D40: =IF(D20<78,0,IF(D20<3333.33,16,IF(D20<6667,((16-(D20-3333.33)*0.0042)),0))) -> 16 | F40: =juillet!G42 -> 114 | G40: =F40+D40 -> 130
A43: NET | D43: =D20-D27-D37+D38+D39+D40 -> 2723.3412 | F43: =juillet!G44 -> 19383.398 | G43: =F43+D43 -> 22106.739
A44: Chéque repas | D44: 56
A45: Avance sur salaire | D45: 500 | F45: NET A PAYER | G45: =D43-D44-D45 -> 2167.3412
A48: Congés (H)
A49: Légaux | B49: =+juillet!B50 -> 208 | C49: Rémunération | F49: Fiche d'impôts
A50: Report | B50: =+juillet!B51 -> -4 | C50: Salaire mensuel | D50: =D51*D52 -> 3244.4 | F50: N° de carte | G50: =juillet!G51 -> D608388-2022
A51: Pris : | B51: =juillet!B52+B18 -> 97 | C51: Heures | D51: =juillet!D52 -> 173 | F51: Classe | G51: =juillet!G52 -> 1
A52: Solde : | B52: =(B50+B49)-B51 -> 107 | C52: Salaire horaire | D52: =juillet!D53 -> 18.753757 | F52: Taux | G52: =juillet!G53 -> -
A54: CONSERVEZ CE BULLETIN DE PAIE SANS LIMITATION DE DUREE

Sheet septembre
A2: DECOMPTE SALAIRE/TRAITEMENT
A5: N° Salarié : | B5: =aout!B5 -> 2 | F5: =aout!F5 -> Groupe Advensys Luxembourg S.A
A6: Indice : | B6: =aout!B6 -> 968,04 | F6: =aout!F6 -> Duarrefstrooss 49
A7: Emploi : | B7: =aout!B7 -> Comptable | F7: =aout!F7 -> L-9964 Huldange
A8: Date d'entrée : | B8: =aout!B8 -> 44455
A9: Matricule assuré : | B9: =aout!B9 -> 1996 0905 124 86 | F9: =aout!F9 -> BERTHE Alexandra
A10: Matricule employeur : | B10: =aout!B10 -> 20152206748 | F10: =aout!F10 -> 93, Duarrefstrooss
A11: Période : | B11: Septembre 2025 | F11: =aout!F11 -> L-9964 Huldange
A12: Les montants sont exprimées en Euros.
A14: Désignation | B14: Quantité (heures) | C14: Valeur | D14: Total | F14: Cumuls M-1 | G14: Total
A16: Appointement | B16: =D49 -> 173 | C16: =D50 -> 18.753757 | D16: =B16*C16 -> 3244.4
A17: Jours fériée | B17: 0 | C17: 0 | D17: 0
A18: Congés (H) | B18: 36 | C18: 0 | D18: 0
A19: Absences Maladie (H)
A20: Total brut | D20: =D16 -> 3244.4 | F20: =aout!G20 -> 25639 | G20: =F20+D20 -> 28883.4
A22: Cotisation
A23: Assurance Maladie | B23: =aout!B23 -> 0.028 | D23: =D20*B23 -> 90.8432 | F23: =aout!G23 -> 728.08954 | G23: =F23+D23 -> 818.93274
A24: A-M Majoration espèce | B24: =aout!B24 -> 0.0025 | D24: =B24*D20 -> 8.111 | F24: =aout!G24 -> 64.0975 | G24: =F24+D24 -> 72.2085
A25: Assurance Pension | B25: =aout!B25 -> 0.08 | D25: =B25*D20 -> 259.552 | F25: =aout!G25 -> 2051.12 | G25: =F25+D25 -> 2310.672
A26: Assurance dépendance | B26: =aout!B26 -> 0.014 | D26: =B26*(D17+D20-675.93) -> 35.95858 | F26: =aout!G26 -> 289.96573 | G26: =F26+D26 -> 325.92431
A27: Total Cotisation | D27: =SUM(D23:D26) -> 394.46478 | F27: =aout!G27 -> 3133.2728 | G27: =F27+D27 -> 3527.7376
A29: Deduction
A30: FD | D30: =aout!D30 -> 0 | F30: =aout!G30 -> 0 | G30: =F30+D30 -> 0
A31: AC | D31: =aout!D31 -> 0 | F31: =aout!G31 -> 0 | G31: =F31+D31 -> 0
A32: FFO | D32: =aout!D32 -> 0 | F32: =aout!G32 -> 0 | G32: =F32+D32 -> 0
A33: FDS | D33: =aout!D33 -> 0 | F33: =aout!G33 -> 0 | G33: =F33+D33 -> 0
A35: Total Imposable | D35: =D20-D23-D24-D25-D30-D31-D32-D33 -> 2885.8938 | F35: =aout!G35 -> 22795.693 | G35: =F35+D35 -> 25681.587
A37: IMPOT | D37: 240.6 | F37: =aout!G37 -> 1863.6 | G37: =F37+D37 -> 2104.2
A38: CISSM | D38: =IF(D20<1800,0,IF(D20<=3000,81,IF(D20>=3600,0,81/600*(3600-D20)))) -> 48.006 | F38: =aout!G38 -> 434.705 | G38: =F38+D38 -> 482.711
A39: CIS-CIP-CIM | D39: =IF(D20<78,0,IF(D20<936,((300+(D20*12-936)*0.029)/12),IF(D20<3333.33,50,IF(D20>6666.5,0,((600-(D20*12-40000)*0.015)/12))))) -> 50 | F39: =aout!G39 -> 400 | G39: =F39+D39 -> 450
A40: CI-CO2 | D40: =IF(D20<78,0,IF(D20<3333.33,16,IF(D20<6667,((16-(D20-3333.33)*0.0042)),0))) -> 16 | F40: =aout!G40 -> 130 | G40: =F40+D40 -> 146
A42: NET | D42: =D20-D27-D37+D38+D39+D40 -> 2723.3412 | F42: =aout!G43 -> 22106.739 | G42: =F42+D42 -> 24830.081
A43: Chéque repas | D43: 56
A44: Avance sur salaire | D44: 600 | F44: NET A PAYER | G44: =D42-D43-D44 -> 2067.3412
A46: Congés (H)
A47: Légaux | B47: =+aout!B49 -> 208 | C47: Rémunération | F47: Fiche d'impôts
A48: Report | B48: =+aout!B50 -> -4 | C48: Salaire mensuel | D48: =D49*D50 -> 3244.4 | F48: N° de carte | G48: =aout!G50 -> D608388-2022
A49: Pris : | B49: =aout!B51+B18 -> 133 | C49: Heures | D49: =aout!D51 -> 173 | F49: Classe | G49: =aout!G51 -> 1
A50: Solde : | B50: =(B48+B47)-B49 -> 71 | C50: Salaire horaire | D50: =aout!D52 -> 18.753757 | F50: Taux | G50: =aout!G52 -> -
A52: CONSERVEZ CE BULLETIN DE PAIE SANS LIMITATION DE DUREE

Sheet octobre
A2: DECOMPTE SALAIRE/TRAITEMENT
A5: N° Salarié : | B5: =septembre!B5 -> 2 | F5: =septembre!F5 -> Groupe Advensys Luxembourg S.A
A6: Indice : | B6: =septembre!B6 -> 968,04 | F6: =septembre!F6 -> Duarrefstrooss 49
A7: Emploi : | B7: =septembre!B7 -> Comptable | F7: =septembre!F7 -> L-9964 Huldange
A8: Date d'entrée : | B8: =septembre!B8 -> 44455
A9: Matricule assuré : | B9: =septembre!B9 -> 1996 0905 124 86 | F9: =septembre!F9 -> BERTHE Alexandra
A10: Matricule employeur : | B10: =septembre!B10 -> 20152206748 | F10: =septembre!F10 -> 93, Duarrefstrooss
A11: Période : | B11: Octobre 2024 | F11: =septembre!F11 -> L-9964 Huldange
A12: Les montants sont exprimées en Euros.
A14: Désignation | B14: Quantité (heures) | C14: Valeur | D14: Total | F14: Cumuls M-1 | G14: Total
A16: Appointement | B16: =D49 -> 173 | C16: =D50 -> 18.753757 | D16: =B16*C16 -> 3244.4
A17: Jours fériée | B17: 0 | C17: 0 | D17: 0
A18: Congés (H) | B18: 0 | C18: 0 | D18: 0
A19: Absences Maladie (H)
A20: Total brut | D20: =D16 -> 3244.4 | F20: =septembre!G20 -> 28883.4 | G20: =F20+D20 -> 32127.8
A22: Cotisation
A23: Assurance Maladie | B23: =septembre!B23 -> 0.028 | D23: =D20*B23 -> 90.8432 | F23: =septembre!G23 -> 818.93274 | G23: =F23+D23 -> 909.77594
A24: A-M Majoration espèce | B24: =septembre!B24 -> 0.0025 | D24: =B24*D20 -> 8.111 | F24: =septembre!G24 -> 72.2085 | G24: =F24+D24 -> 80.3195
A25: Assurance Pension | B25: =septembre!B25 -> 0.08 | D25: =B25*D20 -> 259.552 | F25: =septembre!G25 -> 2310.672 | G25: =F25+D25 -> 2570.224
A26: Assurance dépendance | B26: =septembre!B26 -> 0.014 | D26: =B26*(D20-642.73) -> 36.42338 | F26: =septembre!G26 -> 325.92431 | G26: =F26+D26 -> 362.34769
A27: Total Cotisation | D27: =SUM(D23:D26) -> 394.92958 | F27: =septembre!G27 -> 3527.7376 | G27: =F27+D27 -> 3922.6671
A29: Deduction
A30: FD | D30: =septembre!D30 -> 0 | F30: =septembre!G30 -> 0 | G30: =F30+D30 -> 0
A31: AC | D31: =septembre!D31 -> 0 | F31: =septembre!G31 -> 0 | G31: =F31+D31 -> 0
A32: FFO | D32: =septembre!D32 -> 0 | F32: =septembre!G32 -> 0 | G32: =F32+D32 -> 0
A33: FDS | D33: =septembre!D33 -> 0 | F33: =septembre!G33 -> 0 | G33: =F33+D33 -> 0
A35: Total Imposable | D35: =D20-D23-D24-D25-D30-D31-D32-D33 -> 2885.8938 | F35: =septembre!G35 -> 25681.587 | G35: =F35+D35 -> 28567.481
A37: IMPOT | F37: =septembre!G37 -> 2104.2 | G37: =F37+D37 -> 2104.2
A38: CISSM | D38: =IF(D20<1800,0,IF(D20<=3000,81,IF(D20>=3600,0,81/600*(3600-D20)))) -> 48.006 | F38: =septembre!G38 -> 482.711 | G38: =F38+D38 -> 530.717
A39: CIS-CIP-CIM | D39: =IF(D20<78,0,IF(D20<936,((300+(D20*12-936)*0.029)/12),IF(D20<3333.33,50,IF(D20>6666.5,0,((600-(D20*12-40000)*0.015)/12))))) -> 50 | F39: =septembre!G39 -> 450 | G39: =F39+D39 -> 500
A40: CI-CO2 | D40: =IF(D20<78,0,IF(D20<3333.33,16,IF(D20<6667,((16-(D20-3333.33)*0.0042)),0))) -> 16 | F40: =septembre!G40 -> 146 | G40: =F40+D40 -> 162
A42: NET | D42: =D20-D27-D37+D38+D39+D40 -> 2963.4764 | F42: =septembre!G42 -> 24830.081 | G42: =F42+D42 -> 27793.557
F44: NET A PAYER | G44: =D42 -> 2963.4764
A46: Congés (H)
A47: Légaux | B47: =+septembre!B47 -> 208 | C47: Rémunération | F47: Fiche d'impôts
A48: Report | B48: =+septembre!B48 -> -4 | C48: Salaire mensuel | D48: =D49*D50 -> 3244.4 | F48: N° de carte | G48: =septembre!G48 -> D608388-2022
A49: Pris : | B49: =septembre!B49+B18 -> 133 | C49: Heures | D49: =septembre!D49 -> 173 | F49: Classe | G49: =septembre!G49 -> 1
A50: Solde : | B50: =(B48+B47)-B49 -> 71 | C50: Salaire horaire | D50: =septembre!D50 -> 18.753757 | F50: Taux | G50: =septembre!G50 -> -
A52: CONSERVEZ CE BULLETIN DE PAIE SANS LIMITATION DE DUREE

Sheet novembre
A2: DECOMPTE SALAIRE/TRAITEMENT
A5: N° Salarié : | B5: =octobre!B5 -> 2 | F5: =octobre!F5 -> Groupe Advensys Luxembourg S.A
A6: Indice : | B6: =octobre!B6 -> 968,04 | F6: =octobre!F6 -> Duarrefstrooss 49
A7: Emploi : | B7: =octobre!B7 -> Comptable | F7: =octobre!F7 -> L-9964 Huldange
A8: Date d'entrée : | B8: =octobre!B8 -> 44455
A9: Matricule assuré : | B9: =octobre!B9 -> 1996 0905 124 86 | F9: =octobre!F9 -> BERTHE Alexandra
A10: Matricule employeur : | B10: =octobre!B10 -> 20152206748 | F10: =octobre!F10 -> 93, Duarrefstrooss
A11: Période : | B11: Novembre 2024 | F11: =octobre!F11 -> L-9964 Huldange
A12: Les montants sont exprimées en Euros.
A14: Désignation | B14: Quantité (heures) | C14: Valeur | D14: Total | F14: Cumuls M-1 | G14: Total
A16: Appointement | B16: =D49 -> 173 | C16: =D50 -> 18.753757 | D16: =B16*C16 -> 3244.4
A17: Jours fériée | B17: 8 | C17: 0 | D17: 0
A18: Congés (H) | B18: 0 | C18: 0 | D18: 0
A19: Absences Maladie (H)
A20: Total brut | D20: =D16 -> 3244.4 | F20: =octobre!G20 -> 32127.8 | G20: =F20+D20 -> 35372.2
A22: Cotisation
A23: Assurance Maladie | B23: =octobre!B23 -> 0.028 | D23: =D20*B23 -> 90.8432 | F23: =octobre!G23 -> 909.77594 | G23: =F23+D23 -> 1000.6191
A24: A-M Majoration espèce | B24: =octobre!B24 -> 0.0025 | D24: =B24*D20 -> 8.111 | F24: =octobre!G24 -> 80.3195 | G24: =F24+D24 -> 88.4305
A25: Assurance Pension | B25: =octobre!B25 -> 0.08 | D25: =B25*D20 -> 259.552 | F25: =octobre!G25 -> 2570.224 | G25: =F25+D25 -> 2829.776
A26: Assurance dépendance | B26: =octobre!B26 -> 0.014 | D26: =B26*(D20-642.73) -> 36.42338 | F26: =octobre!G26 -> 362.34769 | G26: =F26+D26 -> 398.77107
A27: Total Cotisation | D27: =SUM(D23:D26) -> 394.92958 | F27: =octobre!G27 -> 3922.6671 | G27: =F27+D27 -> 4317.5967
A29: Deduction
A30: FD | D30: =octobre!D30 -> 0 | F30: =octobre!G30 -> 0 | G30: =F30+D30 -> 0
A31: AC | D31: =octobre!D31 -> 0 | F31: =octobre!G31 -> 0 | G31: =F31+D31 -> 0
A32: FFO | D32: =octobre!D32 -> 0 | F32: =octobre!G32 -> 0 | G32: =F32+D32 -> 0
A33: FDS | D33: =octobre!D33 -> 0 | F33: =octobre!G33 -> 0 | G33: =F33+D33 -> 0
A35: Total Imposable | D35: =D20-D23-D24-D25-D30-D31-D32-D33 -> 2885.8938 | F35: =octobre!G35 -> 28567.481 | G35: =F35+D35 -> 31453.374
A37: IMPOT | F37: =octobre!G37 -> 2104.2 | G37: =F37+D37 -> 2104.2
A38: CISSM | D38: =IF(D20<1800,0,IF(D20<=3000,81,IF(D20>=3600,0,81/600*(3600-D20)))) -> 48.006 | F38: =octobre!G38 -> 530.717 | G38: =F38+D38 -> 578.723
A39: CIS-CIP-CIM | D39: =IF(D20<78,0,IF(D20<936,((300+(D20*12-936)*0.029)/12),IF(D20<3333.33,50,IF(D20>6666.5,0,((600-(D20*12-40000)*0.015)/12))))) -> 50 | F39: =octobre!G39 -> 500 | G39: =F39+D39 -> 550
A40: CI-CO2 | D40: =IF(D20<78,0,IF(D20<3333.33,16,IF(D20<6667,((16-(D20-3333.33)*0.0042)),0))) -> 16 | F40: =octobre!G40 -> 162 | G40: =F40+D40 -> 178
A42: NET | D42: =D20-D27-D37+D38+D39+D40 -> 2963.4764 | F42: =octobre!G42 -> 27793.557 | G42: =F42+D42 -> 30757.033
F44: NET A PAYER | G44: =D42 -> 2963.4764
A46: Congés (H)
A47: Légaux | B47: =octobre!B47 -> 208 | C47: Rémunération | F47: Fiche d'impôts
A48: Report | B48: =+octobre!B48 -> -4 | C48: Salaire mensuel | D48: =D49*D50 -> 3244.4 | F48: N° de carte | G48: =octobre!G48 -> D608388-2022
A49: Pris : | B49: =octobre!B49+B18 -> 133 | C49: Heures | D49: =octobre!D49 -> 173 | F49: Classe | G49: =octobre!G49 -> 1
A50: Solde : | B50: =(B48+B47)-B49 -> 71 | C50: Salaire horaire | D50: =octobre!D50 -> 18.753757 | F50: Taux | G50: =octobre!G50 -> -
A52: CONSERVEZ CE BULLETIN DE PAIE SANS LIMITATION DE DUREE

Sheet décembre
A2: DECOMPTE SALAIRE/TRAITEMENT
A5: N° Salarié : | B5: =novembre!B5 -> 2 | F5: =novembre!F5 -> Groupe Advensys Luxembourg S.A
A6: Indice : | B6: =novembre!B6 -> 968,04 | F6: =novembre!F6 -> Duarrefstrooss 49
A7: Emploi : | B7: =novembre!B7 -> Comptable | F7: =novembre!F7 -> L-9964 Huldange
A8: Date d'entrée : | B8: =novembre!B8 -> 44455
A9: Matricule assuré : | B9: =novembre!B9 -> 1996 0905 124 86 | F9: =novembre!F9 -> BERTHE Alexandra
A10: Matricule employeur : | B10: =novembre!B10 -> 20152206748 | F10: =novembre!F10 -> 93, Duarrefstrooss
A11: Période : | B11: Décembre 2024 | F11: =novembre!F11 -> L-9964 Huldange
A12: Les montants sont exprimées en Euros.
A14: Désignation | B14: Quantité (heures) | C14: Valeur | D14: Total | F14: Cumuls M-1 | G14: Total
A16: Appointement | B16: =D49 -> 173 | C16: =D50 -> 18.753757 | D16: =B16*C16 -> 3244.4
A17: Jours fériée | B17: 16 | C17: 0 | D17: 0
A18: Congés (H) | B18: 0 | C18: 0 | D18: 0
A19: Absences Maladie (H)
A20: Total brut | D20: =D16 -> 3244.4 | F20: =novembre!G20 -> 35372.2 | G20: =F20+D20 -> 38616.6
A22: Cotisation
A23: Assurance Maladie | B23: =novembre!B23 -> 0.028 | D23: =D20*B23 -> 90.8432 | F23: =novembre!G23 -> 1000.6191 | G23: =F23+D23 -> 1091.4623
A24: A-M Majoration espèce | B24: =novembre!B24 -> 0.0025 | D24: =B24*D20 -> 8.111 | F24: =novembre!G24 -> 88.4305 | G24: =F24+D24 -> 96.5415
A25: Assurance Pension | B25: =novembre!B25 -> 0.08 | D25: =B25*D20 -> 259.552 | F25: =novembre!G25 -> 2829.776 | G25: =F25+D25 -> 3089.328
A26: Assurance dépendance | B26: =novembre!B26 -> 0.014 | D26: =B26*(D20-642.73) -> 36.42338 | F26: =novembre!G26 -> 398.77107 | G26: =F26+D26 -> 435.19445
A27: Total Cotisation | D27: =SUM(D23:D26) -> 394.92958 | F27: =novembre!G27 -> 4317.5967 | G27: =F27+D27 -> 4712.5263
A29: Deduction
A30: FD | D30: =novembre!D30 -> 0 | F30: =novembre!G30 -> 0 | G30: =F30+D30 -> 0
A31: AC | D31: =novembre!D31 -> 0 | F31: =novembre!G31 -> 0 | G31: =F31+D31 -> 0
A32: FFO | D32: =novembre!D32 -> 0 | F32: =novembre!G32 -> 0 | G32: =F32+D32 -> 0
A33: FDS | D33: =novembre!D33 -> 0 | F33: =novembre!G33 -> 0 | G33: =F33+D33 -> 0
A35: Total Imposable | D35: =D20-D23-D24-D25-D30-D31-D32-D33 -> 2885.8938 | F35: =novembre!G35 -> 31453.374 | G35: =F35+D35 -> 34339.268
A37: IMPOT | F37: =novembre!G37 -> 2104.2 | G37: =F37+D37 -> 2104.2
A38: CISSM | D38: =IF(D20<1800,0,IF(D20<=3000,81,IF(D20>=3600,0,81/600*(3600-D20)))) -> 48.006 | F38: =novembre!G38 -> 578.723 | G38: =F38+D38 -> 626.729
A39: CIS-CIP-CIM | D39: =IF(D20<78,0,IF(D20<936,((300+(D20*12-936)*0.029)/12),IF(D20<3333.33,50,IF(D20>6666.5,0,((600-(D20*12-40000)*0.015)/12))))) -> 50 | F39: =novembre!G39 -> 550 | G39: =F39+D39 -> 600
A40: CI-CO2 | D40: =IF(D20<78,0,IF(D20<3333.33,16,IF(D20<6667,((16-(D20-3333.33)*0.0042)),0))) -> 16 | F40: =novembre!G40 -> 178 | G40: =F40+D40 -> 194
A42: NET | D42: =D20-D27-D37+D38+D39+D40 -> 2963.4764 | F42: =novembre!G42 -> 30757.033 | G42: =F42+D42 -> 33720.51
F44: NET A PAYER | G44: =D42 -> 2963.4764
A46: Congés (H)
A47: Légaux | B47: =novembre!B47 -> 208 | C47: Rémunération | F47: Fiche d'impôts
A48: Report | B48: =novembre!B48 -> -4 | C48: Salaire mensuel | D48: =D49*D50 -> 3244.4 | F48: N° de carte | G48: =novembre!G48 -> D608388-2022
A49: Pris : | B49: =novembre!B49+B18 -> 133 | C49: Heures | D49: =novembre!D49 -> 173 | F49: Classe | G49: =novembre!G49 -> 1
A50: Solde : | B50: =(B48+B47)-B49 -> 71 | C50: Salaire horaire | D50: =novembre!D50 -> 18.753757 | F50: Taux | G50: =novembre!G50 -> -
A53: CONSERVEZ CE BULLETIN DE PAIE SANS LIMITATION DE DUREE
